Workbook
Name Database: #REF!
Name Database: #REF!
Name dxn: [1]dxnsjtempsheet!$A$1:$G$65536
Name fzxm: '[2]披露表(上市)'!$D$12:$D$23
Name fzxm_qt: '[3]披露表(国资)'!$C$48:$C$65
Name fzxm_xj: '[3]披露表(国资)'!$C$10:$C$27
Name fzxm_yc: '[3]披露表(国资)'!$C$29:$C$46
Name fzxmxj: '[4]披露表(上市)'!$C$11:$C$14
Name fzxmyh: '[4]披露表(上市)'!$C$16:$C$19
Name gzfzxm: '[5]披露表(国资)'!$C$10:$C$11
Name hkd: 1.0611
Name KMDM: #REF!
Name KMDM: #REF!
Name KMDM: #REF!
Name usd: 8.2773
Name 附注: #REF!
Name 附注: #REF!
Name 固定资产清单: #REF!
Name 固定资产清单: #REF!
Name 应付帐款: #REF!
Name 应付帐款: #REF!
Name 应付帐款: #REF!
Name 应收帐款: #REF!
Name 应收帐款: #REF!
Name 应收帐款: #REF!
Name Database: #REF!
Name KMDM: #REF!
Name 附注: #REF!
Name 固定资产清单: #REF!
Name 应付帐款: #REF!
Name 应收帐款: #REF!
Name Database: #REF!
Name KMDM: #REF!
Name 附注: #REF!
Name 固定资产清单: #REF!
Name 应付帐款: #REF!
Name 应收帐款: #REF!
Name Database: #REF!
Name KMDM: #REF!
Name 附注: #REF!
Name 固定资产清单: #REF!
Name 应付帐款: #REF!
Name 应收帐款: #REF!
Name Database: #REF!
Name KMDM: #REF!
Name 附注: #REF!
Name 固定资产清单: #REF!
Name 应付帐款: #REF!
Name 应收帐款: #REF!

Sheet 基本信息
B1: 公司名称 | C1: 简称 | E1: 股权结构图：
A2: 母公司 | B2: 飞而康快速制造科技有限责任公司 | C2: 飞而康快速
A3: 子公司1 | C3: 飞而康新材料
A4: 子公司2 | C4: 飞而康精铸
A5: 子公司3 | C5: 飞而康热等静压 | F5: 待更新
A6: 子公司4
A7: 子公司5
B9: 截止日 | C9: 会计年度
A11: 第一期 | B11: 44926 | C11: 2022年度
A12: 第二期 | B12: 45291 | C12: 2023年度
A13: 第三期 | B13: 45657 | C13: 2024年度
A14: 第四期 | B14: 45991 | C14: 2025年度
B15: 签名 | C15: 日期：
A16: 编制人：
A17: 复核人：

Sheet 利润表-新材料+快速
A1: 利 润 表-合并报表
C2: 会企02表 | D2: =(B5-B8)/B5 -> 0.68475341 | E2: =(C5-C8)/C5 -> 0.17882376 | K2: =(I5-I8)/I5 -> 0.13633661 | L2: =(J5-J8)/J5 -> 0.099941107 | Q2: =C5-C8 -> 23966730 | W2: =W3/W5 -> 0.70725114 | X2: =X3/X5 -> 0.16037483 | Z2: 9585464.7 | AA2: 70777394
A3: 单位名称：飞而康快速制造科技有限责任公司 | B3: =合并试算平衡表!B6 -> 45991 | C3: 单位：元 | F3: 注意修改！！！ | Q3: =Q2/C5 -> 0.17882376 | W3: =W5-W8 -> 11607351 | X3: =X5-X8 -> 19692046 | Z3: =W5-Z2 -> 6826458.7 | AA3: =X5-AA2 -> 52010240 | AC3: =AA5-AA8 -> 9056400.4 | AD3: 差异系精铸管理费嘎差
A4: 项 目 | B4: 合并口径本期金额 | C4: 合并口径本年累计金额 | E4: =(D5-E8)/D5 -> #DIV/0! | F4: 2410月金额 | G4: 2410月累计金额 | I4: 2306数据 | J4: 2306合计 | K4: 差异1 | L4: 差异2 | Q4: 精铸本月 | R4: 精铸累计 | S4: 热等静压本月 | T4: 热等静压累计 | U4: 合并抵消还原本月 | V4: 合并抵消还原累计 | W4: 快速+新材料本期金额 | X4: 快速+新材料本年累计金额
A5: 一、营业收入 | B5: =C5-G5 -> 17635913 | C5: =C6+C7 -> 1.340243e+08 | F5: 17470608 | G5: 1.1638839e+08 | I5: 14520603 | J5: 46494371 | K5: =B5-I5 -> 3115309.8 | L5: =C5-J5 -> 87529932 | M5: =K5/I5 -> 0.21454411 | N5: =L5/J5 -> 1.882592 | Q5: =精铸PL!B5 -> 757088.85 | R5: =精铸PL!C5 -> 6894779.8 | S5: =热等静压PL!B5 -> 1375041.3 | T5: =热等静压PL!C5 -> 18429412 | U5: =SUM(U6:U7) -> 908140.93 | V5: =SUM(V6:V7) -> 14087523 | W5: =B5-Q5-S5+U5 -> 16411923 | X5: =C5-R5-T5+V5 -> 1.2278763e+08 | Z5: =W5-新材料PL!D6-快速PL!C6 -> -1276342 | AA5: =X5-新材料PL!E6-快速PL!D6 -> -1.2233872e+08
A6: 其中：主营业务收入 | B6: =C6-G6 -> 18206795 | C6: =合并试算平衡表!K125 -> 1.3352726e+08 | F6: 17406946 | G6: 1.1532047e+08 | I6: 14326059 | J6: 45162004 | K6: =B6-I6 -> 3880735.7 | L6: =C6-J6 -> 88365258 | M6: =K6/I6 -> 0.27088647 | N6: =L6/J6 -> 1.9566284 | Q6: =精铸PL!B6 -> 757088.85 | R6: =精铸PL!C6 -> 6890832.9 | S6: =热等静压PL!B6 -> 1375041.3 | T6: =热等静压PL!C6 -> 18429412 | U6: =66814.16+717929.94 -> 784744.1 | V6: =252654.87+12342539.58 -> 12595194 | W6: =B6-Q6-S6+U6 -> 16859409 | X6: =C6-R6-T6+V6 -> 1.2080221e+08 | Z6: =W6-新材料PL!D7-快速PL!C7 -> -133883.45 | AA6: =X6-新材料PL!E7-快速PL!D7 -> -1.0035663e+08 | AC6: =93137171.52 -> 93137172
A7: 其他业务收入 | B7: =C7-G7 -> -570882.32 | C7: =合并试算平衡表!K126 -> 497041.45 | F7: 63662.36 | G7: 1067923.8 | I7: 194543.53 | J7: 1332367.7 | K7: =B7-I7 -> -765425.85 | L7: =C7-J7 -> -835326.27 | M7: =K7/I7 -> -3.9344709 | N7: =L7/J7 -> -0.62694875 | Q7: =精铸PL!B7 -> 0 | R7: =精铸PL!C7 -> 3946.9 | S7: =热等静压PL!B7 -> 0 | T7: =热等静压PL!C7 -> 0 | U7: 123396.83 | V7: 1492328.1 | W7: =B7-Q7-S7+U7 -> -447485.49 | X7: =C7-R7-T7+V7 -> 1985422.6 | Z7: =W7-新材料PL!D8-快速PL!C8 -> -1142458.5 | AA7: =X7-新材料PL!E8-快速PL!D8 -> -21982083 | AC7: =3909115.43-合并调整抵消分录!F224 -> 3909115.4
A8: 减：营业成本 | B8: =C8-G8 -> 5559661.3 | C8: =C9+C10 -> 1.1005757e+08 | F8: 15004809 | G8: 1.0449791e+08 | I8: 12540913 | J8: 41847672 | K8: =B8-I8 -> -6981251.6 | L8: =C8-J8 -> 68209901 | M8: =K8/I8 -> -0.5566781 | N8: =L8/J8 -> 1.6299569 | Q8: =精铸PL!B8 -> 765142.84 | R8: =精铸PL!C8 -> 5464056.9 | S8: =热等静压PL!B8 -> 876946.02 | T8: =热等静压PL!C8 -> 15352894 | U8: =U9+U10 -> 886999.42 | V8: =V9+V10 -> 13854966 | W8: =B8-Q8-S8+U8 -> 4804571.9 | X8: =C8-R8-T8+V8 -> 1.0309559e+08 | Z8: =W8-新材料PL!D9-快速PL!C9 -> -11959845 | AA8: =X8-新材料PL!E9-快速PL!D9 -> -1.3139512e+08
A9: 其中：主营业务成本 | B9: =C9-G9 -> 6384482.1 | C9: =合并试算平衡表!K128 -> 1.1005757e+08 | F9: 14981283 | G9: 1.0367309e+08 | I9: 12420465 | J9: 41161831 | K9: =B9-I9 -> -6035982.6 | L9: =C9-J9 -> 68895742 | M9: =K9/I9 -> -0.48597075 | N9: =L9/J9 -> 1.6737774 | Q9: =精铸PL!B9 -> 765142.84 | R9: =精铸PL!C9 -> 5464056.9 | S9: =热等静压PL!B9 -> 876946.02 | T9: =热等静压PL!C9 -> 15352894 | U9: =U6 -> 784744.1 | V9: =V6 -> 12595194 | W9: =B9-Q9-S9+U9 -> 5527137.4 | X9: =C9-R9-T9+V9 -> 1.0183582e+08 | Z9: =W9-新材料PL!D10-快速PL!C10 -> -10586565 | AA9: =X9-新材料PL!E10-快速PL!D10 -> -1.0918221e+08
A10: 其他业务成本 | B10: =C10-G10 -> -824820.83 | C10: =合并试算平衡表!K129 -> 0 | F10: 23525.8 | G10: 824820.83 | I10: 120448.22 | J10: 685841.17 | K10: =B10-I10 -> -945269.05 | L10: =C10-J10 -> -685841.17 | M10: =K10/I10 -> -7.8479288 | N10: =L10/J10 -> -1 | Q10: =精铸PL!B10 -> 0 | R10: =精铸PL!C10 -> 0 | S10: =热等静压PL!B10 -> 0 | T10: =热等静压PL!C10 -> 0 | U10: =U7-U13 -> 102255.32 | V10: =V7-V13 -> 1259771.5 | W10: =B10-Q10-S10+U10 -> -722565.51 | X10: =C10-R10-T10+V10 -> 1259771.5 | Z10: =W10-新材料PL!D11-快速PL!C11 -> -1373280.1 | AA10: =X10-新材料PL!E11-快速PL!D11 -> -22212905
A11: 营业税金及附加 | B11: =C11-G11 -> -997712.24 | C11: =合并试算平衡表!K130 -> 829444.38 | D11: =C11/$C$5 -> 0.006188761 | E11: =D5*0.007 -> 0 | F11: 71444.48 | G11: 1827156.6 | I11: 90103.84 | J11: 475596.62 | K11: =B11-I11 -> -1087816.1 | L11: =C11-J11 -> 353847.76 | M11: =K11/I11 -> -12.072916 | N11: =L11/J11 -> 0.74400815 | O11: 快速资产转移新材料4月份开票确认收入6227.38形成增值税 809.56 及附加税97.15万元 | Q11: =精铸PL!B11 -> 4572.03 | R11: =精铸PL!C11 -> 27595.05 | S11: =热等静压PL!B11 -> 1020.39 | T11: =热等静压PL!C11 -> 6811.17 | W11: =B11-Q11-S11+U11 -> -1003304.7 | X11: =C11-R11-T11+V11 -> 795038.16 | Z11: =W11-新材料PL!D12-快速PL!C12 -> -1061049.2 | AA11: =X11-新材料PL!E12-快速PL!D12 -> -1061049.2
A12: 销售费用 | B12: =C12-G12 -> -521103.68 | C12: =合并试算平衡表!K131 -> 8045698 | D12: =C12/$C$5 -> 0.060031634 | E12: =D12*$D$5 -> 0 | F12: 964070.03 | G12: 8566801.7 | I12: 938241.48 | J12: 4692976 | K12: =B12-I12 -> -1459345.2 | L12: =C12-J12 -> 3352722 | M12: =K12/I12 -> -1.5554046 | N12: =L12/J12 -> 0.71441277 | O12: 营业收入增长，销售费用略有增长相对合理 | Q12: =精铸PL!B12 -> 48065.29 | R12: =精铸PL!C12 -> 533425.91 | S12: =热等静压PL!B12 -> 117870.1 | T12: =热等静压PL!C12 -> 641148.73 | W12: =B12-Q12-S12+U12 -> -687039.07 | X12: =C12-R12-T12+V12 -> 6871123.3 | Z12: =W12-新材料PL!D13-快速PL!C13 -> -2731662.9 | AA12: =X12-新材料PL!E13-快速PL!D13 -> -2731662.9
A13: 管理费用 | B13: =C13-G13 -> -766556.38 | C13: =合并试算平衡表!K132 -> 8350965.1 | D13: =C13/$C$5 -> 0.062309334 | E13: =D13*$D$5 -> 0 | F13: 891664.76 | G13: 9117521.4 | I13: 941704.85 | J13: 4286617.3 | K13: =B13-I13 -> -1708261.2 | L13: =C13-J13 -> 4064347.8 | M13: =K13/I13 -> -1.8140092 | N13: =L13/J13 -> 0.94814803 | O13: 上年同期因审计调整，红冲当月费用26.20万元 | Q13: =精铸PL!B13 -> 66954.09 | R13: =精铸PL!C13 -> 635654.87 | S13: =热等静压PL!B13 -> 37604.38 | T13: =热等静压PL!C13 -> 446142.54 | U13: 21141.51 | V13: 232556.61 | W13: =B13-Q13-S13+U13 -> -849973.34 | X13: =C13-R13-T13+V13 -> 7501724.3 | Z13: =W13-新材料PL!D14-快速PL!C14 -> -1534749.7 | AA13: =X13-新材料PL!E14-快速PL!D14 -> -1534749.7
A14: 研发费用 | B14: =C14-G14 -> 942695.37 | C14: =合并试算平衡表!K133 -> 19920178 | D14: =C14/$C$5 -> 0.14863109 | E14: =D14*$D$5 -> 0 | F14: 2625421.1 | G14: 18977483 | I14: 1386872.1 | J14: 8292064.8 | K14: =B14-I14 -> -444176.74 | L14: =C14-J14 -> 11628113 | M14: =K14/I14 -> -0.32027231 | N14: =L14/J14 -> 1.4023182 | O14: 上年同期将1-3月部分误入3D生产成本的研发费用调整调回研发费用-直接投入 | Q14: =精铸PL!B14 -> 23475.81 | R14: =精铸PL!C14 -> 652802.07 | S14: =热等静压PL!B14 -> 166797.05 | T14: =热等静压PL!C14 -> 892711.12 | W14: =B14-Q14-S14+U14 -> 752422.51 | X14: =C14-R14-T14+V14 -> 18374665 | Z14: =W14-新材料PL!D15-快速PL!C15 -> -4055269 | AA14: =X14-新材料PL!E15-快速PL!D15 -> -4055269
A15: 财务费用 | B15: =C15-G15 -> -224415.61 | C15: =合并试算平衡表!K134 -> 4508765.3 | D15: =C15/$C$5 -> 0.033641401 | E15: =D15*$D$5 -> 0 | F15: 400727.74 | G15: 4733180.9 | I15: 523640.15 | J15: 2939834.1 | K15: =B15-I15 -> -748055.76 | L15: =C15-J15 -> 1568931.2 | M15: =K15/I15 -> -1.4285684 | N15: =L15/J15 -> 0.53368016 | O15: 跟产业集团借款3000万元，每月约增加15万财务费用 | Q15: =精铸PL!B15 -> 20294.88 | R15: =精铸PL!C15 -> 175284.93 | S15: =热等静压PL!B15 -> 416.99 | T15: =热等静压PL!C15 -> -2452.71 | U15: 0 | V15: 0 | W15: =B15-Q15-S15+U15 -> -245127.48 | X15: =C15-R15-T15+V15 -> 4335933.1 | Z15: =W15-新材料PL!D16-快速PL!C16 -> -659752.5 | AA15: =X15-新材料PL!E16-快速PL!D16 -> -659752.5
A16: 资产减值损失 | B16: =C16-G16 -> 0 | C16: =合并试算平衡表!K140 -> 0 | F16: 0 | G16: 0 | I16: 0 | J16: -7500 | K16: =B16-I16 -> 0 | L16: =C16-J16 -> 7500 | W16: =B16-Q16-S16+U16 -> 0 | X16: =C16-R16-T16+V16 -> 0
A17: 信用减值损失 | B17: =C17-G17 -> -579092.11 | C17: =合并试算平衡表!K139 -> -1780058.3 | F17: 0 | G17: -1200966.1 | K17: =B17-I17 -> -579092.11 | L17: =C17-J17 -> -1780058.3 | Q17: =-精铸PL!B17 -> 0 | R17: =精铸PL!C17 -> 45991.45 | S17: =-热等静压PL!B17 -> 0 | T17: =热等静压PL!C17 -> -139781.06 | W17: =B17-Q17-S17+U17 -> -579092.11 | X17: =C17-R17-T17+V17 -> -1686268.6 | Z17: =W17+新材料PL!D18+快速PL!C18 -> -579092.11 | AA17: =X17+新材料PL!E18+快速PL!D18 -> -2793445.2
A18: 加：公允价值变动收益（损失以"-"填列） | B18: =C18-G18 -> 0 | C18: 0 | F18: 0 | G18: 0 | K18: =B18-I18 -> 0 | L18: =C18-J18 -> 0 | W18: =B18-Q18-S18+U18 -> 0 | X18: =C18-R18-T18+V18 -> 0
A19: 投资收益（损失以"-"填列） | B19: =C19-G19 -> 713796.94 | C19: =合并试算平衡表!K136 -> 853056.55 | F19: 3.4924597e-10 | G19: 139259.61 | I19: 12833.33 | J19: 94275.86 | K19: =B19-I19 -> 700963.61 | L19: =C19-J19 -> 758780.69 | W19: =B19-Q19-S19+U19 -> 713796.94 | X19: =C19-R19-T19+V19 -> 853056.55 | AA19: 2411
A20: 其中：对联营企业和合营企业的投资收益 | B20: =C20-G20 -> 0 | C20: 0 | F20: 0 | G20: 0 | K20: =B20-I20 -> 0 | L20: =C20-J20 -> 0 | W20: =B20-Q20-S20+U20 -> 0 | X20: =C20-R20-T20+V20 -> 0 | Z20: 236635.29 | AA20: 新材料-热压背靠背收入
A21: 其他收益 | B21: =C21-G21 -> 622840.85 | C21: =合并试算平衡表!K135 -> 1305528.3 | F21: 165040 | G21: 682687.46 | I21: 0 | J21: 153443.41 | K21: =B21-I21 -> 622840.85 | L21: =C21-J21 -> 1152084.9 | Q21: =精铸PL!B21 -> 175000 | R21: =精铸PL!C21 -> 559647.46 | S21: =热等静压PL!B21 -> 0 | T21: =热等静压PL!C21 -> 0 | W21: =B21-Q21-S21+U21 -> 447840.85 | X21: =C21-R21-T21+V21 -> 745880.85 | Z21: =AB28+AB31+AB32 -> 14465224 | AA21: 3D
A22: 二、营业利润（亏损以"－"号填列） | B22: =C22-G22 -> 14400889 | C22: =C5-C8-C11-C12-C13-C14-C15+C16+C18+C19+C21+C17 -> -17309794 | F22: -2322488.7 | G22: -31710684 | I22: -1888039.3 | J22: -15785171 | K22: =B22-I22 -> 16288929 | L22: =C22-J22 -> -1524623.8 | Q22: =Q5-Q8-Q11-Q12-Q13-Q14-Q15+Q16+Q18+Q19+Q21+Q17 -> 3583.91 | R22: =R5-R8-R11-R12-R13-R14-R15+R16+R18+R19+R21+R17 -> 11598.91 | S22: =S5-S8-S11-S12-S13-S14-S15+S16+S18+S19+S21+S17 -> 174386.35 | T22: =T5-T8-T11-T12-T13-T14-T15+T16+T18+T19+T21+T17 -> 952375.44 | W22: =W5-W8-W11-W12-W13-W14-W15+W16+W18+W19+W21+W17 -> 14222919 | X22: =X5-X8-X11-X12-X13-X14-X15+X16+X18+X19+X21+X17 -> -18273769 | Z22: =SUM(Z20:Z21) -> 14701860 | AA22: 合计
A23: 加：营业外收入 | B23: =C23-G23 -> -119902.09 | C23: =合并试算平衡表!K143 -> 70120.03 | F23: 0 | G23: 190022.12 | I23: 250001.17 | J23: 2016411 | K23: =B23-I23 -> -369903.26 | L23: =C23-J23 -> -1946291 | Q23: =精铸PL!B23 -> 0 | R23: =精铸PL!C23 -> 3.03 | S23: =热等静压PL!B23 -> 0 | T23: =热等静压PL!C23 -> 1.73 | W23: =B23-Q23-S23+U23 -> -119902.09 | X23: =C23-R23-T23+V23 -> 70115.27 | Z23: =Z22-W6 -> -2157549.2 | AA23: check
A24: 减：营业外支出 | B24: =C24-G24 -> 15755.35 | C24: =合并试算平衡表!K145 -> 24203.21 | F24: 0 | G24: 8447.86 | I24: 15.66 | J24: 341.48 | K24: =B24-I24 -> 15739.69 | L24: =C24-J24 -> 23861.73 | Q24: =精铸PL!B24 -> 592.32 | R24: =精铸PL!C24 -> 3130.45 | S24: =热等静压PL!B24 -> 0 | T24: =热等静压PL!C24 -> 0 | W24: =B24-Q24-S24+U24 -> 15163.03 | X24: =C24-R24-T24+V24 -> 21072.76
A25: 其中：非流动资产处置损失 | B25: =C25-G25 -> 0 | C25: 0 | F25: 0 | G25: 0 | K25: =B25-I25 -> 0 | L25: =C25-J25 -> 0 | W25: 0 | X25: 0
A26: 三、利润总额（亏损总额以"－"号填列） | B26: =C26-G26 -> 14265232 | C26: =C22+C23-C24 -> -17263878 | F26: -2322488.7 | G26: -31529110 | I26: -1638053.8 | J26: -13769101 | K26: =B26-I26 -> 15903286 | L26: =C26-J26 -> -3494776.6 | Q26: =Q22+Q23-Q24 -> 2991.59 | R26: =R22+R23-R24 -> 8471.49 | S26: =S22+S23-S24 -> 174386.35 | T26: =T22+T23-T24 -> 952377.17 | W26: =W22+W23-W24 -> 14087854 | X26: =X22+X23-X24 -> -18224726
A27: 减：所得税费用 | B27: =C27-G27 -> 6470.17 | C27: =合并试算平衡表!K148 -> 45634.12 | F27: 0 | G27: 39163.95 | I27: 0 | J27: 11520.73 | K27: =B27-I27 -> 6470.17 | L27: =C27-J27 -> 34113.39 | Q27: =精铸PL!B27 -> 0 | R27: =精铸PL!C27 -> 0 | S27: =热等静压PL!B27 -> 8505.93 | T27: =热等静压PL!C27 -> 47669.88 | W27: =B27-Q27-S27+U27 -> -2035.76 | X27: =C27-R27-T27+V27 -> -2035.76 | AA27: 3D实际开票 | AB27: 14327638
A28: 四、净利润（净亏损以"－"号填列） | B28: =C28-G28 -> 14258762 | C28: =C26-C27 -> -17309512 | F28: -2322488.7 | G28: -31568274 | I28: -1638053.8 | J28: -13780622 | K28: =B28-I28 -> 15896816 | L28: =C28-J28 -> -3528890 | Q28: =Q26-Q27 -> 2991.59 | R28: =R26-R27 -> 8471.49 | S28: =S26-S27 -> 165880.42 | T28: =T26-T27 -> 904707.29 | W28: =W26-W27 -> 14089890 | X28: =X26-X27 -> -18222691 | AA28: 其中账面进收入 | AB28: 13946191
A29: 少数股东损益 | B29: =C29-G29 -> 42034.239 | C29: =合并试算平衡表!K151 -> 43251.883 | F29: 15808.25 | G29: 1217.6438 | I29: 123837 | J29: -122541.82 | K29: =B29-I29 -> -81802.764 | L29: =C29-J29 -> 165793.7 | AA29: 合同负债 | AB29: 381446.66
A30: 归属于母公司所有者的净利润 | B30: =C30-G30 -> 14216728 | C30: =合并试算平衡表!K150 -> -17352764 | F30: -2338296.9 | G30: -31569491 | I30: -1761890.8 | J30: -13658080 | K30: =B30-I30 -> 15978618 | L30: =C30-J30 -> -3694683.7 | AA30: 其余月份合同资产转收入
A31: 五、每股收益： | B31: 0 | C31: 0 | F31: 0 | G31: 0 | AA31: 快速 | AB31: 28141.6
A32: （一）基本每股收益 | AA32: 新材料 | AB32: 490891.59
A33: （二）稀释每股收益
Q34: =精铸PL!B28 -> 2991.59 | R34: =精铸PL!C28 -> 8471.49 | S34: =热等静压PL!B28 -> 165880.42 | T34: =热等静压PL!C28 -> 904707.29 | W34: =W28-B28+精铸PL!B28+热等静压PL!B28 -> -5.5297278e-09 | X34: =X28-C28+精铸PL!C28+热等静压PL!C28 -> -8.6147338e-09
P35: check | Q35: =Q28-Q34 -> 0 | R35: =R28-R34 -> 0 | S35: =S28-S34 -> -9.6042641e-10 | T35: =T28-T34 -> 0

Sheet 资产负债表-合并(原）
A1: 资产负债表-合并报表
G2: 会企01表
A3: 单位名称：飞而康快速制造科技有限责任公司 | E3: ='利润表-合并'!B3 -> 45991 | G3: 单位：元
A5: 资产 | B5: 年初余额 | C5: 期末余额 | E5: 负债及所有者权益（或股东权益） | F5: 年初余额 | G5: 期末余额
A6: 流动资产： | E6: 流动负债：
A7: 货币资金 | B7: 47919713 | C7: =合并试算平衡表!K9 -> 56972677 | D7: =(C7-B7)/B7 -> 0.18891941 | E7: 短期借款 | F7: 62800000 | G7: =合并试算平衡表!K64 -> 1.1655207e+08 | H7: =(F7-G7)/F7 -> -0.85592467
A8: 其中：银行存款 | B8: 40494291 | C8: =精铸BS!C7+新材料BS!D7+快速BS!D7+热等静压BS!C7 -> 21767935 | D8: =(C8-B8)/B8 -> -0.46244434 | E8: 交易性金融负债 | H8: =(F8-G8)/F8 -> #DIV/0!
A9: 其他货币资金 | B9: 7415709.8 | C9: =精铸BS!C8+新材料BS!D8+快速BS!D8+热等静压BS!C8 -> 504397.14 | D9: =(C9-B9)/B9 -> -0.93198262 | E9: 应付票据 | F9: 13567983 | G9: =合并试算平衡表!K70 -> 1128557.5 | H9: =(F9-G9)/F9 -> 0.91682202
A10: 交易性金融资产 | B10: 6000000 | C10: =合并试算平衡表!K12 -> 0 | D10: =(C10-B10)/B10 -> -1 | E10: 应付账款 | F10: 97313283 | G10: =合并试算平衡表!K71 -> 1.4933087e+08 | H10: =(F10-G10)/F10 -> -0.53453742
A11: 应收票据 | B11: 7578956.6 | C11: =合并试算平衡表!K14 -> 6766158.5 | D11: =(C11-B11)/B11 -> -0.10724406 | E11: 预收款项 | F11: 412768.62 | G11: =合并试算平衡表!K72 -> 3510493.9 | H11: =(F11-G11)/F11 -> -7.5047499
A12: 应收账款 | B12: 75509438 | C12: =合并试算平衡表!K15 -> 1.1533203e+08 | D12: =(C12-B12)/B12 -> 0.52738556 | E12: 合同负债 | F12: 0 | G12: =合并试算平衡表!K73 -> 5289418 | H12: =(F13-G13)/F13 -> 0.47642887
A13: 预付款项 | B13: 1306843.1 | C13: =合并试算平衡表!K17 -> 7259283.4 | D13: =(C13-B13)/B13 -> 4.554824 | E13: 应付职工薪酬 | F13: 6096722.6 | G13: =合并试算平衡表!K76 -> 3192067.9 | H13: =(F14-G14)/F14 -> 5.7735915
A14: 应收利息 | B14: 0 | C14: =合并试算平衡表!K21 -> 0 | D14: =(C14-B14)/B14 -> #DIV/0! | E14: 应交税费 | F14: -154621.2 | G14: =合并试算平衡表!K77 -> 738098.44 | H14: =(F15-G15)/F15 -> -1.9100214
A15: 应收股利 | B15: 0 | C15: =合并试算平衡表!K22 -> 0 | D15: =(C15-B15)/B15 -> #DIV/0! | E15: 应付利息 | F15: 156763.89 | G15: =合并试算平衡表!K78 -> 456186.27 | H15: =(F16-G16)/F16 -> #DIV/0!
A16: 其他应收款 | B16: 2584018.1 | C16: =合并试算平衡表!K23 -> 721163.11 | D16: =(C16-B16)/B16 -> -0.72091407 | E16: 应付股利 | F16: 0 | G16: =合并试算平衡表!K79 -> 0 | H16: =(F17-G17)/F17 -> -1.8438671
A17: 存货 | B17: 1.0119038e+08 | C17: =合并试算平衡表!K25 -> 1.1331129e+08 | D17: =(C17-B17)/B17 -> 0.11978326 | E17: 其他应付款 | F17: 1224220.3 | G17: =合并试算平衡表!K80 -> 3481519.8 | H17: =(F18-G18)/F18 -> 0.65286407
A18: 其中：库存材料 | B18: 36662265 | C18: =精铸BS!C17+新材料BS!D17+快速BS!D17+热等静压BS!C17 -> 34576849 | D18: =(C18-B18)/B18 -> -0.056881824 | E18: 一年内到期的非流动负债 | F18: 36447159 | G18: =合并试算平衡表!K86+合并试算平衡表!K87 -> 12652118 | H18: =(F32-G32)/F32 -> -15.878876 | L18: 合并报表 | N18: 精铸 | O18: 新材料 | P18: 快速准 | Q18: 快速
A19: 在产品及自制半成品 | B19: 21132635 | C19: =精铸BS!C18+新材料BS!D18+快速BS!D18+热等静压BS!C18 -> 21228692 | D19: =(C19-B19)/B19 -> 0.0045454678 | H19: =(F20-G20)/F20 -> #DIV/0! | K19: =(C19-B19)/0.75 -> 128076.95 | L19: =K19/10000 -> 12.807695 | M19: 在产品产值 | N19: =(精铸BS!C18-精铸BS!B18)/0.75/10000 -> 549.15123 | O19: =(新材料BS!D18-新材料BS!C18)/0.75/10000 -> 348.42395 | P19: =Q19+R19 -> -884.76749 | Q19: =(快速BS!D18-快速BS!C18)/0.75/10000 -> -1045.6513 | R19: =L19-N19-O19-Q19 -> 160.8838
A20: 产成品（库存商品） | B20: 41755341 | C20: =精铸BS!C19+新材料BS!D19+快速BS!D19+热等静压BS!C19 -> 44092937 | D20: =(C20-B20)/B20 -> 0.055983157 | F20: 0 | G20: 0 | H20: =(F21-G21)/F21 -> #DIV/0! | K20: =(C20-B20)/0.75+'利润表-合并'!C5 -> 1.371411e+08 | L20: =K20/10000 -> 13714.11 | M20: 产成品产值 | N20: =((精铸BS!C19-精铸BS!B19)/0.75+精铸PL!C5)/10000 -> 192.74859 | O20: =((新材料BS!D19-新材料BS!C19)/0.75+新材料PL!E6)/10000 -> 16099.64 | P20: =Q20+R20 -> -2578.2785 | Q20: =((快速BS!D19-快速BS!C19)/0.75+快速PL!D6)/10000 -> 9242.9093 | R20: =L20-N20-O20-Q20 -> -11821.188
A21: 周转材料 | B21: 1640134.3 | C21: =精铸BS!C20+新材料BS!D20+快速BS!D20+热等静压BS!C20 -> 1114684.8 | D21: =(C21-B21)/B21 -> -0.3203698 | F21: 0 | G21: 0 | H21: =(F22-G22)/F22 -> #DIV/0! | K21: =K19+K20 -> 1.3726917e+08 | L21: =L19+L20 -> 13726.917 | M21: 总产值 | N21: =N19+N20 -> 741.89983 | O21: =O19+O20 -> 16448.064 | P21: =Q21+R21 -> -3463.046 | Q21: =Q19+Q20 -> 8197.258 | R21: =L21-N21-O21-Q21 -> -11660.304
A22: 待摊费用 | D22: =(C22-B22)/B22 -> #DIV/0! | F22: 0 | G22: 0 | H22: =(F23-G23)/F23 -> #DIV/0!
A23: 合同资产 | F23: 0 | G23: 0
A24: 一年内到期的非流动资产 | B24: 0 | C24: =合并试算平衡表!K28 -> 0 | D24: =(C24-B24)/B24 -> #DIV/0! | H24: =(F25-G25)/F25 -> -0.36016516
A25: 其他流动资产 | B25: 477319.67 | C25: =合并试算平衡表!K29 -> 3625070.3 | D25: =(C25-B25)/B25 -> 6.5946383 | E25: 流动负债合计 | F25: 2.1786428e+08 | G25: =SUM(G7:G23) -> 2.963314e+08 | H25: =(F26-G26)/F26 -> #DIV/0! | I25: =G25/10000 -> 29633.14
A26: 流动资产合计 | B26: 2.4256666e+08 | C26: =C7+C10+C11+C12+C13+C16+C17+C22+C25 -> 3.0398767e+08 | D26: =(C26-B26)/B26 -> 0.25321288 | E26: 非流动负债： | F26: 0 | G26: 0 | H26: =(F27-G27)/F27 -> 0.0258 | K26: =K19/1.13+K20 -> 1.3725444e+08 | L26: =K26/10000 -> 13725.444 | M26: 工业销售产值 | N26: =((精铸BS!C18-精铸BS!B18+精铸BS!C19-精铸BS!B19)+精铸PL!C5)/10000 -> 728.79436 | O26: =((新材料BS!C18-新材料BS!B18+新材料BS!C19-新材料BS!B19)+新材料PL!C6)/10000 -> 730.52332 | P26: =Q26+R26 -> #VALUE! | Q26: =((快速BS!C18-快速BS!B18+快速BS!C19-快速BS!B19)+快速PL!C5)/10000 -> #VALUE! | R26: =L26-N26-O26-Q26 -> #VALUE!
A27: 非流动资产： | B27: 0 | C27: 0 | D27: =(C27-B27)/B27 -> #DIV/0! | E27: 长期借款 | F27: 50000000 | G27: =合并试算平衡表!K90 -> 48710000 | H27: =(F28-G28)/F28 -> #DIV/0!
A28: 可供出售金融资产 | B28: 0 | C28: =合并试算平衡表!K33 -> 0 | D28: =(C28-B28)/B28 -> #DIV/0! | E28: 应付债券 | F28: 0 | G28: =合并试算平衡表!K91 -> 0 | H28: =(F29-G29)/F29 -> 1
A29: 持有至到期投资 | B29: 0 | C29: =合并试算平衡表!K34 -> 0 | D29: =(C29-B29)/B29 -> #DIV/0! | E29: 长期应付款 | F29: 2497172.2 | G29: =合并试算平衡表!K94 -> 0 | H29: =(F30-G30)/F30 -> #DIV/0!
A30: 长期应收款 | B30: 28650 | C30: =合并试算平衡表!K35 -> 0 | D30: =(C30-B30)/B30 -> -1 | E30: 专项应付款 | F30: 0 | G30: 0 | H30: =(F31-G31)/F31 -> #DIV/0!
A31: 长期股权投资 | B31: 0 | C31: =合并试算平衡表!K36 -> 0 | D31: =(C31-B31)/B31 -> #DIV/0! | E31: 预计负债 | H31: =(F33-G33)/F33 -> #DIV/0!
A32: 投资性房地产 | B32: 0 | C32: =合并试算平衡表!K39 -> 0 | D32: =(C32-B32)/B32 -> #DIV/0! | E32: 递延收益 | F32: 2010252.9 | G32: =合并试算平衡表!K98 -> 33930809 | H32: =(F34-G34)/F34 -> #DIV/0!
A33: 固定资产原价 | B33: 3.2774819e+08 | C33: =合并试算平衡表!K40 -> 3.6376163e+08 | D33: =(C33-B33)/B33 -> 0.10988142 | E33: 递延所得税负债 | F33: 0 | G33: =合并试算平衡表!K99 -> 0 | H33: =(F35-G35)/F35 -> -0.51613855 | K33: =C33-B33 -> 36013437 | L33: =ROUND(K33/10000,2) -> 3601.34 | M33: 固定资产当年增加
A34: 减：累计折旧 | B34: 1.1518926e+08 | C34: =合并试算平衡表!K41 -> 1.6850946e+08 | D34: =(C34-B34)/B34 -> 0.46289213 | E34: 其他非流动负债 | F34: 0 | G34: =合并试算平衡表!K100 -> 0 | H34: =(F36-G36)/F36 -> -0.39137879 | K34: =C34-B34 -> 53320202 | L34: =ROUND(K34/10000,2) -> 5332.02 | M34: 当年累计折旧
A35: 固定资产净值 | B35: 2.1255893e+08 | C35: =C33-C34 -> 1.9525217e+08 | D35: =(C35-B35)/B35 -> -0.081421021 | E35: 非流动负债合计 | F35: 54507425 | G35: =SUM(G27:G34) -> 82640809 | H35: =(F37-G37)/F37 -> #DIV/0!
A36: 在建工程 | B36: 16725442 | C36: =合并试算平衡表!K45 -> 42663260 | D36: =(C36-B36)/B36 -> 1.5508002 | E36: 负债合计 | F36: 2.723717e+08 | G36: =G25+G35 -> 3.7897221e+08 | H36: =(F38-G38)/F38 -> -0.009973253
A37: 工程物资 | B37: 0 | C37: =合并试算平衡表!K46 -> 0 | D37: =(C37-B37)/B37 -> #DIV/0! | E37: 所有者权益（或股东权益）： | F37: 0 | G37: 0 | H37: =(F39-G39)/F39 -> -0.11786555
A38: 固定资产清理 | B38: 0 | C38: =合并试算平衡表!K47 -> 0 | D38: =(C38-B38)/B38 -> #DIV/0! | E38: 实收资本（或股本） | F38: 260216000 | G38: =合并试算平衡表!K104 -> 262811200 | H38: =(F40-G40)/F40 -> #DIV/0!
A39: 生产性生物资产 | B39: 0 | C39: =合并试算平衡表!K48 -> 0 | D39: =(C39-B39)/B39 -> #DIV/0! | E39: 资本公积 | F39: 1.0524534e+08 | G39: =合并试算平衡表!K108 -> 1.1765014e+08 | H39: =(F41-G41)/F41 -> #DIV/0!
A40: 油气资产 | B40: 0 | C40: =合并试算平衡表!K49 -> 0 | D40: =(C40-B40)/B40 -> #DIV/0! | E40: 减：库存股 | H40: =(F42-G42)/F42 -> -0.43249189
A41: 无形资产 | B41: 12866865 | C41: =合并试算平衡表!K50 -> 13011878 | D41: =(C41-B41)/B41 -> 0.011270254 | E41: 盈余公积 | F41: 0 | G41: =合并试算平衡表!K112 -> 0 | H41: =(F43-G43)/F43 -> 0.19048863
...

Sheet BS-合并
A1: 资产负债表-合并
F2: 会企01表
A3: 制表单位:飞而康快速制造科技有限责任公司 | C3: 报表期间： | D3: =基本信息!B14 -> 45991 | E3: 单位: | F3: 人民币元
A7: 资产 | B7: 年初余额 | C7: 期末余额 | D7: 负债及所有者权益 | E7: 年初余额 | F7: 期末余额
A8: 流动资产： | D8: 流动负债：
A9: 货币资金 | B9: 49753272 | C9: =合并试算平衡表!K9 -> 56972677 | D9: 短期借款 | E9: 1.0278669e+08 | F9: =合并试算平衡表!K64 -> 1.1655207e+08
A10: 其中：银行存款 | B10: 49750882 | C10: =精铸BS新!C10+新材料BS新!C6+快速BS新!C10+热等静压BS新!C7 -> 56240462 | D10: 交易性金融负债 | E10: 0 | F10: =合并试算平衡表!K67 -> 0
A11: 其他货币资金 | B11: 2389.71 | C11: =精铸BS新!C11+新材料BS新!C7+快速BS新!C11+热等静压BS新!C8 -> 732215.19 | D11: 应付票据 | E11: 0 | F11: =合并试算平衡表!K70 -> 1128557.5
A12: 交易性金融资产 | B12: 0 | C12: =合并试算平衡表!K12 -> 0 | D12: 应付账款 | E12: 1.1834943e+08 | F12: =合并试算平衡表!K71 -> 1.4933087e+08
A13: 应收票据 | B13: 29226386 | C13: =合并试算平衡表!K14 -> 6766158.5 | D13: 预收账款 | E13: 0 | F13: =合并试算平衡表!K72 -> 3510493.9
A14: 应收账款 | B14: 86579419 | C14: =合并试算平衡表!K15 -> 1.1533203e+08 | D14: 合同负债 | E14: 9067703.6 | F14: =合并试算平衡表!K73 -> 5289418
A15: 应收款项融资 | B15: 1603892.3 | C15: =合并试算平衡表!K16 -> 0 | D15: 应付职工薪酬 | E15: 7566027.5 | F15: =合并试算平衡表!K76 -> 3192067.9
A16: 预付款项 | B16: 4883049.8 | C16: =合并试算平衡表!K17 -> 7259283.4 | D16: 应交税费 | E16: 3095811.7 | F16: =合并试算平衡表!K77 -> 738098.44
A17: 应收利息 | B17: 0 | C17: =合并试算平衡表!K21 -> 0 | D17: 应付利息 | E17: 0 | F17: =合并试算平衡表!K78 -> 456186.27
A18: 应收股利 | B18: 0 | C18: =合并试算平衡表!K22 -> 0 | D18: 应付股利 | E18: 0 | F18: =合并试算平衡表!K79 -> 0
A19: 其他应收款 | B19: 938609.95 | C19: =合并试算平衡表!K23 -> 721163.11 | D19: 其他应付款 | E19: 1627343.6 | F19: =合并试算平衡表!K80 -> 3481519.8
A20: 存货 | B20: 89565843 | C20: =合并试算平衡表!K25 -> 1.1331129e+08 | D20: 一年内到期的非流动负债 | E20: 35008704 | F20: =合并试算平衡表!K86 -> 8372322.7
A21: 其中:库存材料 | B21: 34587133 | C21: =快速BS新!C21+新材料BS新!C17+热等静压BS新!C18+精铸BS新!C21-合并调整抵消分录!F196-合并调整抵消分录!F177 -> 34837507 | D21: 其他流动负债 | E21: 22779924 | F21: =合并试算平衡表!K87 -> 4279795.6
A22: 在产品及自制半成品 | B22: 20928300 | C22: =快速BS新!C22+新材料BS新!C18+热等静压BS新!C19+精铸BS新!C22 -> 31121988 | H22: =(C22-B22)/0.75/10000 -> 1359.1583 | I22: 在产品产值
A23: 产成品(库存商品) | B23: 33022501 | C23: =快速BS新!C23+新材料BS新!C19+热等静压BS新!C20+精铸BS新!C23 -> 46329411 | H23: =((C23-B23)/0.75+'PL-合并'!D9)/10000 -> 15176.685 | I23: 产成品产值
A24: 周转材料 | B24: 1027908.9 | C24: =快速BS新!C24+新材料BS新!C20+热等静压BS新!C21+精铸BS新!C24 -> 1022383.5 | H24: =H22+H23 -> 16535.843 | I24: 总产值
A25: 待摊费用 | B25: 0 | C25: 0 | D25: 流动负债合计 | E25: =SUM(E9:E24) -> 3.0028163e+08 | F25: =SUM(F9:F24) -> 2.963314e+08 | H25: =H22/1.13+H23 -> 16379.48 | I25: 工业销售产值
A26: 合同资产 | B26: 5174733.3 | C26: =合并试算平衡表!K26 -> 1426653 | D26: 非流动负债： | E26: ——
A27: 一年内到期的非流动资产 | B27: 0 | C27: =合并试算平衡表!K28 -> 0 | D27: 长期借款 | E27: 23800000 | F27: =合并试算平衡表!K90 -> 48710000
A28: 其他流动资产 | B28: 1383995.4 | C28: =合并试算平衡表!K29 -> 3625070.3 | D28: 应付债券 | E28: 0 | F28: =合并试算平衡表!K91 -> 0
A29: 流动资产合计 | B29: =SUM(B9:B28)-B10-B11-B21-B22-B23-B24 -> 2.691092e+08 | C29: =SUM(C9:C28)-C10-C11-C21-C22-C23-C24 -> 3.0541432e+08 | D29: 长期应付款 | E29: 0 | F29: =合并试算平衡表!K94 -> 0
D30: 专项应付款 | E30: 0 | F30: =合并试算平衡表!K96 -> 0
D31: 预计负债 | E31: 0 | F31: =合并试算平衡表!K97 -> 0
D32: 递延收益 | E32: 6958008.6 | F32: =合并试算平衡表!K98 -> 33930809
A33: 非流动资产： | D33: 递延所得税负债 | E33: 0 | F33: =合并试算平衡表!K99 -> 0
A34: 可供出售金融资产 | B34: 0 | C34: =合并试算平衡表!K33 -> 0 | D34: 其他非流动负债 | E34: 0 | F34: =合并试算平衡表!K100 -> 0
A35: 持有至到期投资 | B35: 0 | C35: =合并试算平衡表!K34 -> 0 | D35: 非流动负债合计 | E35: =SUM(E27:E34) -> 30758009 | F35: =SUM(F27:F34) -> 82640809
A36: 长期应收款 | B36: 0 | C36: =合并试算平衡表!K35 -> 0 | D36: 负债合计 | E36: =E35+E25 -> 3.3103964e+08 | F36: =F35+F25 -> 3.7897221e+08
A37: 长期股权投资 | B37: 0 | C37: =合并试算平衡表!K36 -> 0
A38: 其他非流动金融资产 | B38: 17507066 | C38: =合并试算平衡表!K38 -> 3000000
A39: 投资性房地产 | B39: 0 | C39: =合并试算平衡表!K39 -> 0 | D39: 所有者权益（或股东权益）： | E39: ——
A40: 固定资产 | B40: 3.4408716e+08 | C40: =合并试算平衡表!K40 -> 3.6376163e+08 | D40: 实收资本（或股本） | E40: 260216000 | F40: =合并试算平衡表!K104 -> 262811200 | H40: =(C40-B40)/10000 -> 1967.4474 | I40: 固定资产当年增加
A41: 减:累计折旧 | B41: 1.4300318e+08 | C41: =合并试算平衡表!K41 -> 1.6850946e+08 | D41: 资本公积 | E41: 1.0524534e+08 | F41: =合并试算平衡表!K108 -> 1.1765014e+08 | H41: =(C41-B41)/10000 -> 2550.6277 | I41: 当年累计折旧
A42: 固定资产净值 | B42: 2.0108397e+08 | C42: =C40-C41 -> 1.9525217e+08 | D42: 减：库存股 | E42: 0 | F42: =合并试算平衡表!K109 -> 0
A43: 在建工程 | B43: 11313317 | C43: =合并试算平衡表!K45 -> 42663260 | D43: 盈余公积 | E43: 0 | F43: =合并试算平衡表!K112 -> 0
...

Sheet 利润表-合并
A1: 利 润 表-合并报表
C2: 会企02表 | D2: =(B5-B8)/B5 -> 0.68475341 | E2: =(C5-C8)/C5 -> 0.17882376 | K2: =(I5-I8)/I5 -> 0.13633661 | L2: =(J5-J8)/J5 -> 0.099941107
A3: 单位名称：飞而康快速制造科技有限责任公司 | B3: =合并试算平衡表!B6 -> 45991 | C3: 单位：元 | F3: 注意修改！！！
A4: 项 目 | B4: 本期金额 | C4: 本年累计金额 | E4: =(D5-E8)/D5 -> #DIV/0! | F4: 2410月金额 | G4: 2410月累计金额 | I4: 2306数据 | J4: 2306合计 | K4: 差异1 | L4: 差异2
A5: 一、营业收入 | B5: =C5-G5 -> 17635913 | C5: =C6+C7 -> 1.340243e+08 | F5: 17470608 | G5: 1.1638839e+08 | I5: 14520603 | J5: 46494371 | K5: =B5-I5 -> 3115309.8 | L5: =C5-J5 -> 87529932 | M5: =K5/I5 -> 0.21454411 | N5: =L5/J5 -> 1.882592
A6: 其中：主营业务收入 | B6: =C6-G6 -> 18206795 | C6: =合并试算平衡表!K125 -> 1.3352726e+08 | F6: 17406946 | G6: 1.1532047e+08 | I6: 14326059 | J6: 45162004 | K6: =B6-I6 -> 3880735.7 | L6: =C6-J6 -> 88365258 | M6: =K6/I6 -> 0.27088647 | N6: =L6/J6 -> 1.9566284
A7: 其他业务收入 | B7: =C7-G7 -> -570882.32 | C7: =合并试算平衡表!K126 -> 497041.45 | F7: 63662.36 | G7: 1067923.8 | I7: 194543.53 | J7: 1332367.7 | K7: =B7-I7 -> -765425.85 | L7: =C7-J7 -> -835326.27 | M7: =K7/I7 -> -3.9344709 | N7: =L7/J7 -> -0.62694875
A8: 减：营业成本 | B8: =C8-G8 -> 5559661.3 | C8: =C9+C10 -> 1.1005757e+08 | F8: 15004809 | G8: 1.0449791e+08 | I8: 12540913 | J8: 41847672 | K8: =B8-I8 -> -6981251.6 | L8: =C8-J8 -> 68209901 | M8: =K8/I8 -> -0.5566781 | N8: =L8/J8 -> 1.6299569
A9: 其中：主营业务成本 | B9: =C9-G9 -> 6384482.1 | C9: =合并试算平衡表!K128 -> 1.1005757e+08 | F9: 14981283 | G9: 1.0367309e+08 | I9: 12420465 | J9: 41161831 | K9: =B9-I9 -> -6035982.6 | L9: =C9-J9 -> 68895742 | M9: =K9/I9 -> -0.48597075 | N9: =L9/J9 -> 1.6737774
A10: 其他业务成本 | B10: =C10-G10 -> -824820.83 | C10: =合并试算平衡表!K129 -> 0 | F10: 23525.8 | G10: 824820.83 | I10: 120448.22 | J10: 685841.17 | K10: =B10-I10 -> -945269.05 | L10: =C10-J10 -> -685841.17 | M10: =K10/I10 -> -7.8479288 | N10: =L10/J10 -> -1
A11: 营业税金及附加 | B11: =C11-G11 -> -997712.24 | C11: =合并试算平衡表!K130 -> 829444.38 | D11: =C11/$C$5 -> 0.006188761 | E11: =D5*0.007 -> 0 | F11: 71444.48 | G11: 1827156.6 | I11: 90103.84 | J11: 475596.62 | K11: =B11-I11 -> -1087816.1 | L11: =C11-J11 -> 353847.76 | M11: =K11/I11 -> -12.072916 | N11: =L11/J11 -> 0.74400815 | O11: 快速资产转移新材料4月份开票确认收入6227.38形成增值税 809.56 及附加税97.15万元
A12: 销售费用 | B12: =C12-G12 -> -521103.68 | C12: =合并试算平衡表!K131 -> 8045698 | D12: =C12/$C$5 -> 0.060031634 | E12: =D12*$D$5 -> 0 | F12: 964070.03 | G12: 8566801.7 | I12: 938241.48 | J12: 4692976 | K12: =B12-I12 -> -1459345.2 | L12: =C12-J12 -> 3352722 | M12: =K12/I12 -> -1.5554046 | N12: =L12/J12 -> 0.71441277 | O12: 营业收入增长，销售费用略有增长相对合理
A13: 管理费用 | B13: =C13-G13 -> -766556.38 | C13: =合并试算平衡表!K132 -> 8350965.1 | D13: =C13/$C$5 -> 0.062309334 | E13: =D13*$D$5 -> 0 | F13: 891664.76 | G13: 9117521.4 | I13: 941704.85 | J13: 4286617.3 | K13: =B13-I13 -> -1708261.2 | L13: =C13-J13 -> 4064347.8 | M13: =K13/I13 -> -1.8140092 | N13: =L13/J13 -> 0.94814803 | O13: 上年同期因审计调整，红冲当月费用26.20万元
A14: 研发费用 | B14: =C14-G14 -> 942695.37 | C14: =合并试算平衡表!K133 -> 19920178 | D14: =C14/$C$5 -> 0.14863109 | E14: =D14*$D$5 -> 0 | F14: 2625421.1 | G14: 18977483 | I14: 1386872.1 | J14: 8292064.8 | K14: =B14-I14 -> -444176.74 | L14: =C14-J14 -> 11628113 | M14: =K14/I14 -> -0.32027231 | N14: =L14/J14 -> 1.4023182 | O14: 上年同期将1-3月部分误入3D生产成本的研发费用调整调回研发费用-直接投入
A15: 财务费用 | B15: =C15-G15 -> -224415.61 | C15: =合并试算平衡表!K134 -> 4508765.3 | D15: =C15/$C$5 -> 0.033641401 | E15: =D15*$D$5 -> 0 | F15: 400727.74 | G15: 4733180.9 | I15: 523640.15 | J15: 2939834.1 | K15: =B15-I15 -> -748055.76 | L15: =C15-J15 -> 1568931.2 | M15: =K15/I15 -> -1.4285684 | N15: =L15/J15 -> 0.53368016 | O15: 跟产业集团借款3000万元，每月约增加15万财务费用
A16: 资产减值损失 | B16: =C16-G16 -> 0 | C16: =合并试算平衡表!K140 -> 0 | D16: 11月修改取数逻辑 | F16: 0 | G16: 0 | I16: 0 | J16: -7500 | K16: =B16-I16 -> 0 | L16: =C16-J16 -> 7500
A17: 信用减值损失 | B17: =C17-G17 -> -579092.11 | C17: =合并试算平衡表!K139 -> -1780058.3 | D17: 11月修改取数逻辑 | F17: 0 | G17: -1200966.1 | K17: =B17-I17 -> -579092.11 | L17: =C17-J17 -> -1780058.3
A18: 加：公允价值变动收益（损失以"-"填列） | B18: =C18-G18 -> 0 | C18: 0 | F18: 0 | G18: 0 | K18: =B18-I18 -> 0 | L18: =C18-J18 -> 0
A19: 投资收益（损失以"-"填列） | B19: =C19-G19 -> 713796.94 | C19: =合并试算平衡表!K136 -> 853056.55 | F19: 3.4924597e-10 | G19: 139259.61 | I19: 12833.33 | J19: 94275.86 | K19: =B19-I19 -> 700963.61 | L19: =C19-J19 -> 758780.69
A20: 其中：对联营企业和合营企业的投资收益 | B20: =C20-G20 -> 0 | C20: 0 | F20: 0 | G20: 0 | K20: =B20-I20 -> 0 | L20: =C20-J20 -> 0
A21: 其他收益 | B21: =C21-G21 -> 622840.85 | C21: =合并试算平衡表!K135 -> 1305528.3 | F21: 165040 | G21: 682687.46 | I21: 0 | J21: 153443.41 | K21: =B21-I21 -> 622840.85 | L21: =C21-J21 -> 1152084.9
A22: 二、营业利润（亏损以"－"号填列） | B22: =C22-G22 -> 14400889 | C22: =C5-C8-C11-C12-C13-C14-C15+C16+C18+C19+C21+C17 -> -17309794 | D22: 11月修改取数公式 | F22: -2322488.7 | G22: -31710684 | I22: -1888039.3 | J22: -15785171 | K22: =B22-I22 -> 16288929 | L22: =C22-J22 -> -1524623.8
A23: 加：营业外收入 | B23: =C23-G23 -> -119902.09 | C23: =合并试算平衡表!K143 -> 70120.03 | F23: 0 | G23: 190022.12 | I23: 250001.17 | J23: 2016411 | K23: =B23-I23 -> -369903.26 | L23: =C23-J23 -> -1946291
A24: 减：营业外支出 | B24: =C24-G24 -> 15755.35 | C24: =合并试算平衡表!K145 -> 24203.21 | F24: 0 | G24: 8447.86 | I24: 15.66 | J24: 341.48 | K24: =B24-I24 -> 15739.69 | L24: =C24-J24 -> 23861.73
A25: 其中：非流动资产处置损失 | B25: =C25-G25 -> 0 | C25: 0 | F25: 0 | G25: 0 | K25: =B25-I25 -> 0 | L25: =C25-J25 -> 0
A26: 三、利润总额（亏损总额以"－"号填列） | B26: =C26-G26 -> 14265232 | C26: =C22+C23-C24 -> -17263878 | F26: -2322488.7 | G26: -31529110 | I26: -1638053.8 | J26: -13769101 | K26: =B26-I26 -> 15903286 | L26: =C26-J26 -> -3494776.6
A27: 减：所得税费用 | B27: =C27-G27 -> 6470.17 | C27: =合并试算平衡表!K148 -> 45634.12 | F27: 0 | G27: 39163.95 | I27: 0 | J27: 11520.73 | K27: =B27-I27 -> 6470.17 | L27: =C27-J27 -> 34113.39
A28: 四、净利润（净亏损以"－"号填列） | B28: =C28-G28 -> 14258762 | C28: =C26-C27 -> -17309512 | F28: -2322488.7 | G28: -31568274 | I28: -1638053.8 | J28: -13780622 | K28: =B28-I28 -> 15896816 | L28: =C28-J28 -> -3528890
A29: 少数股东损益 | B29: =C29-G29 -> 42034.239 | C29: =合并试算平衡表!K151 -> 43251.883 | F29: 15808.25 | G29: 1217.6438 | I29: 123837 | J29: -122541.82 | K29: =B29-I29 -> -81802.764 | L29: =C29-J29 -> 165793.7
A30: 归属于母公司所有者的净利润 | B30: =C30-G30 -> 14216728 | C30: =合并试算平衡表!K150 -> -17352764 | F30: -2338296.9 | G30: -31569491 | I30: -1761890.8 | J30: -13658080 | K30: =B30-I30 -> 15978618 | L30: =C30-J30 -> -3694683.7
A31: 五、每股收益： | B31: 0 | C31: 0 | F31: 0 | G31: 0
A32: （一）基本每股收益
A33: （二）稀释每股收益
D40: =B14/B5 -> 0.053453167 | E40: =C14/C5 -> 0.14863109

Sheet PL-合并
A1: 利润表-合并
D2: 会企02表
A3: 制表单位:飞而康快速制造科技有限责任公司 | B3: 报表期间: | C3: =基本信息!B14 -> 45991 | D3: 单位：人民币元 | G3: =C9-C12 -> 676410.62 | H3: =D9-D12 -> 23966730
A6: 账簿:快速主账簿 | C6: =(C9-C12)/C9 -> 0.040977553 | D6: =(D9-D12)/D9 -> 0.17882376 | G6: =(G9-G12)/G9 -> 0.028482909 | H6: =(H9-H12)/H9 -> 0.19818606 | I6: =(C10-C13)/C10 -> 0.038459216 | J6: =(D10-D13)/D10 -> 0.17576702
G7: 注意修改！！！
A8: 项目 | B8: 行次 | C8: 本期金额 | D8: 本年累计金额 | G8: 2510月金额 | H8: 2510月累计金额 | M8: 合并 | N8: 3D
A9: 一、营业收入 | B9: 1 | C9: =D9-H9 -> 16506857 | D9: =D10+D11 -> 1.340243e+08 | G9: 11456714 | H9: 1.1751745e+08 | L9: 累计收入 | M9: =D9/10000 -> 13402.43 | N9: ='PL-3D板块'!R9/10000 -> 9547.7146
A10: 其中：主营业务收入 | B10: 2 | C10: =D10-H10 -> 16463625 | D10: =合并试算平衡表!K125 -> 1.3352726e+08 | G10: 11391609 | H10: 1.1706364e+08 | L10: 净利润 | M10: =D36/10000 -> -1730.9512 | N10: ='PL-3D板块'!R36/10000 -> -3260.4715
A11: 其他业务收入 | B11: 3 | C11: =D11-H11 -> 43232.51 | D11: =合并试算平衡表!K126 -> 497041.45 | G11: 65104.29 | H11: 453808.94
A12: 减：营业成本 | B12: 4 | C12: =D12-H12 -> 15830447 | D12: =D13+D14 -> 1.1005757e+08 | G12: 11130393 | H12: 94227126 | J12: =C18/C9 -> 0.26141189 | K12: =D18/D9 -> 0.14863109
A13: 其中：主营业务成本 | B13: 5 | C13: =D13-H13 -> 15830447 | D13: =合并试算平衡表!K128 -> 1.1005757e+08 | G13: 11130393 | H13: 94227126
A14: 其他业务成本 | B14: 6 | C14: =D14-H14 -> 0 | D14: =合并试算平衡表!K129 -> 0 | G14: 0 | H14: 0
A15: 税金及附加 | B15: 7 | C15: =D15-H15 -> 82112.72 | D15: =合并试算平衡表!K130 -> 829444.38 | G15: 69676.53 | H15: 747331.66
A16: 销售费用 | B16: 8 | C16: =D16-H16 -> 822770.64 | D16: =合并试算平衡表!K131 -> 8045698 | G16: 649038.84 | H16: 7222927.3
A17: 管理费用 | B17: 9 | C17: =D17-H17 -> 1193327.4 | D17: =合并试算平衡表!K132 -> 8350965.1 | G17: 828962.78 | H17: 7157637.6
A18: 研发费用 | B18: 10 | C18: =D18-H18 -> 4315088.8 | D18: =合并试算平衡表!K133 -> 19920178 | G18: 1995821 | H18: 15605089
A19: 财务费用 | B19: 11 | C19: =D19-H19 -> 468077.9 | D19: =合并试算平衡表!K134 -> 4508765.3 | G19: 414734.8 | H19: 4040687.4
A20: 其中：利息费用 | B20: 12 | C20: =D20-H20 -> 458409.52 | D20: =精铸PL新!D20+新材料PL新!D16+快速PL新!D20+热等静压PL新!D16 -> 4534024.2 | G20: 409021.01 | H20: 4075614.6
A21: 利息收入 | B21: 13 | C21: =D21-H21 -> -232.59 | D21: =精铸PL新!D21+新材料PL新!D17+快速PL新!D21+热等静压PL新!D17 -> -85075.68 | G21: 0 | H21: -84843.09
A22: 加：其他收益 | B22: 14 | C22: =D22-H22 -> 250000 | D22: =合并试算平衡表!K135 -> 1305528.3 | G22: 0 | H22: 1055528.3
A23: 投资收益（损失以“-”号填列） | B23: 15 | C23: =D23-H23 -> 0 | D23: =合并试算平衡表!K136 -> 853056.55 | G23: 0 | H23: 853056.55
A24: 其中：对联营企业和合营企业的投资收益 | B24: 16 | C24: =D24-H24 -> 0 | G24: 0
A25: 以摊余成本计量的金融资产终止确认收益（损失以“-”号填列） | B25: 17 | C25: =D25-H25 -> 0 | G25: 0
A26: 净敞口套期收益（损失以“-”号填列） | B26: 18 | C26: =D26-H26 -> 0 | G26: 0
A27: 公允价值变动收益（损失以“-”填列） | B27: 19 | C27: =D27-H27 -> 0 | D27: =合并试算平衡表!K138 -> 0 | G27: 0 | H27: 0
A28: 信用减值损失（损失以“-”填列） | B28: 20 | C28: =D28-H28 -> 0 | D28: =合并试算平衡表!K139 -> -1780058.3 | G28: 0 | H28: -1780058.3 | I28: =C28/10000 -> 0
A29: 资产减值损失（损失以“-”填列） | B29: 21 | C29: =D29-H29 -> 0 | D29: =合并试算平衡表!K140 -> 0 | G29: 0 | H29: 0
A30: 资产处置收益（损失以“-”填列） | B30: 22 | C30: =D30-H30 -> 0 | D30: =合并试算平衡表!K141 -> 0 | G30: 0 | H30: 0
A31: 二、营业利润（亏损以“－”号填列） | B31: 23 | C31: =C9-C12-C15-C16-C17-C18-C19+C22+C23+C27+C28+C29+C30 -> -5954966.8 | D31: =D9-D12-D15-D16-D17-D18-D19+D22+D23+D27+D28+D29+D30 -> -17309794 | G31: -3631913.4 | H31: -11354828
A32: 加：营业外收入 | B32: 24 | C32: =D32-H32 -> 0 | D32: =合并试算平衡表!K143 -> 70120.03 | G32: 70000 | H32: 70120.03
A33: 减：营业外支出 | B33: 25 | C33: =D33-H33 -> 0 | D33: =合并试算平衡表!K145 -> 24203.21 | G33: 0.01 | H33: 24203.21
A34: 三、利润总额（亏损以“－”号填列） | B34: 26 | C34: =C31+C32-C33 -> -5954966.8 | D34: =D31+D32-D33 -> -17263878 | G34: -3561913.4 | H34: -11308911
A35: 减：所得税费用 | B35: 27 | C35: =D35-H35 -> 20876.67 | D35: =合并试算平衡表!K148 -> 45634.12 | G35: 0 | H35: 24757.45
A36: 四、净利润（净亏损以“－”号填列） | B36: 28 | C36: =C34-C35 -> -5975843.5 | D36: =D34-D35 -> -17309512 | G36: -3561913.4 | H36: -11333668
A37: 少数股东损益 | B37: 29 | C37: =D37-H37 -> 72653.383 | D37: =合并试算平衡表!K151 -> 43251.883 | G37: 35159.516 | H37: -29401.5
A38: 归属于母公司所有者的净利润 | B38: 30 | C38: =D38-H38 -> -6048496.9 | D38: =合并试算平衡表!K150 -> -17352764 | G38: -3597072.9 | H38: -11304267
A39: 五、其他综合收益的税后净额 | B39: 31
A40: （一）不能重分类进损益的其他综合收益 | B40: 32
A41: 1、重新计量设定受益计划变动额 | B41: 33
A42: 2、权益法下不能转损益的其他综合收益 | B42: 34
...

Sheet 资产负债表-合并 (2)
A1: 资产负债表-合并报表
G2: 会企01表
A3: 单位名称：飞而康快速制造科技有限责任公司 | E3: ='利润表-合并'!B3 -> 45991 | G3: 单位：元
A5: 资产 | B5: 年初余额 | C5: 期末余额 | E5: 负债及所有者权益（或股东权益） | F5: 年初余额 | G5: 期末余额
A6: 流动资产： | E6: 流动负债：
A7: 货币资金 | B7: 53038385 | C7: =合并试算平衡表!K9 -> 56972677 | D7: =(C7-B7)/B7 -> 0.074178214 | E7: 短期借款 | F7: 62878115 | G7: =合并试算平衡表!K64 -> 1.1655207e+08 | H7: =(F7-G7)/F7 -> -0.853619
A8: 其中：银行存款 | B8: 40494241 | C8: =精铸BS!C7+新材料BS!D7+快速BS!D7+热等静压BS!C7 -> 21767935 | D8: =(C8-B8)/B8 -> -0.46244367 | E8: 交易性金融负债 | H8: =(F8-G8)/F8 -> #DIV/0!
A9: 其他货币资金 | B9: 12544099 | C9: =精铸BS!C8+新材料BS!D8+快速BS!D8+热等静压BS!C8 -> 504397.14 | D9: =(C9-B9)/B9 -> -0.95979009 | E9: 应付票据 | F9: 13567983 | G9: =合并试算平衡表!K70 -> 1128557.5 | H9: =(F9-G9)/F9 -> 0.91682202
A10: 交易性金融资产 | B10: 1000000 | C10: =合并试算平衡表!K12 -> 0 | D10: =(C10-B10)/B10 -> -1 | E10: 应付账款 | F10: 96923783 | G10: =合并试算平衡表!K71 -> 1.4933087e+08 | H10: =(F10-G10)/F10 -> -0.54070414
A11: 应收票据 | B11: =19238095.92+5358921.48 -> 24597017 | C11: =合并试算平衡表!K14 -> 6766158.5 | D11: =(C11-B11)/B11 -> -0.72491955 | E11: 预收款项 | G11: =合并试算平衡表!K72 -> 3510493.9 | H11: =(F11-G11)/F11 -> #DIV/0!
A12: 应收账款 | B12: 73111333 | C12: =合并试算平衡表!K15 -> 1.1533203e+08 | D12: =(C12-B12)/B12 -> 0.57748491 | E12: 合同负债 | F12: 1253516.7 | G12: =合并试算平衡表!K73 -> 5289418 | H12: =(F13-G13)/F13 -> 0.25977706
A13: 预付款项 | B13: 2052438.6 | C13: =合并试算平衡表!K17 -> 7259283.4 | D13: =(C13-B13)/B13 -> 2.5369065 | E13: 应付职工薪酬 | F13: 4312306.1 | G13: =合并试算平衡表!K76 -> 3192067.9 | H13: =(F14-G14)/F14 -> -0.4984176
A14: 应收利息 | C14: =合并试算平衡表!K21 -> 0 | D14: =(C14-B14)/B14 -> #DIV/0! | E14: 应交税费 | F14: 492585.27 | G14: =合并试算平衡表!K77 -> 738098.44 | H14: =(F15-G15)/F15 -> #DIV/0!
A15: 应收股利 | C15: =合并试算平衡表!K22 -> 0 | D15: =(C15-B15)/B15 -> #DIV/0! | E15: 应付利息 | G15: =合并试算平衡表!K78 -> 456186.27 | H15: =(F16-G16)/F16 -> #DIV/0! | J15: =C17-C18-C19-C20-C21 -> 12320014
A16: 其他应收款 | B16: 2579303.7 | C16: =合并试算平衡表!K23 -> 721163.11 | D16: =(C16-B16)/B16 -> -0.72040396 | E16: 应付股利 | F16: 0 | G16: =合并试算平衡表!K79 -> 0 | H16: =(F17-G17)/F17 -> -1.8724236
A17: 存货 | B17: 95998497 | C17: =合并试算平衡表!K25 -> 1.1331129e+08 | D17: =(C17-B17)/B17 -> 0.1803444 | E17: 其他应付款 | F17: 1212049.6 | G17: =合并试算平衡表!K80 -> 3481519.8 | H17: =(F18-G18)/F18 -> 0.7711703
A18: 其中：库存材料 | B18: =41437340.57-3089719.68 -> 38347621 | C18: =精铸BS!C17+新材料BS!D17+快速BS!D17+热等静压BS!C17-合并调整抵消分录!F196-合并调整抵消分录!F177 -> 34554960 | D18: =(C18-B18)/B18 -> -0.098902105 | E18: 一年内到期的非流动负债 | F18: 36587571 | G18: =合并试算平衡表!K86 -> 8372322.7 | H18: =(F32-G32)/F32 -> -5.2281142 | I18: 17500000 | J18: 2410长期借款 | L18: 合并报表 | N18: 精铸 | O18: 新材料 | P18: 快速准 | Q18: 快速
A19: 在产品及自制半成品 | B19: 16077130 | C19: =精铸BS!C18+新材料BS!D18+快速BS!D18+热等静压BS!C18 -> 21228692 | D19: =(C19-B19)/B19 -> 0.32042801 | E19: 其他流动负债 | F19: 17887902 | G19: =合并试算平衡表!K87 -> 4279795.6 | H19: =(F20-G20)/F20 -> #DIV/0! | I19: 32500000 | J19: 一年内到期长期借款 | K19: =(C19-B19)/0.75 -> 6868750.3 | L19: =K19/10000 -> 686.87503 | M19: 在产品产值 | N19: =(精铸BS!C18-精铸BS!B18)/0.75/10000 -> 549.15123 | O19: =(新材料BS!D18-新材料BS!C18)/0.75/10000 -> 348.42395 | P19: =Q19+R19 -> -210.70015 | Q19: =(快速BS!D18-快速BS!C18)/0.75/10000 -> -1045.6513 | R19: =L19-N19-O19-Q19 -> 834.95113
A20: 产成品（库存商品） | B20: =12629783.6+32755178.75-3811216.38 -> 41573746 | C20: =精铸BS!C19+新材料BS!D19+快速BS!D19+热等静压BS!C19 -> 44092937 | D20: =(C20-B20)/B20 -> 0.060595709 | G20: 0 | H20: =(F21-G21)/F21 -> #DIV/0! | I20: =G18-I19 -> -24127677 | J20: 一年内到期长期应付 | K20: =(C20-B20)/0.75+'利润表-合并'!C5 -> 1.3738322e+08 | L20: =K20/10000 -> 13738.322 | M20: 产成品产值 | N20: =((精铸BS!C19-精铸BS!B19)/0.75+精铸PL!C5)/10000 -> 192.74859 | O20: =((新材料BS!D19-新材料BS!C19)/0.75+新材料PL!E6)/10000 -> 16099.64 | P20: =Q20+R20 -> -2554.0658 | Q20: =((快速BS!D19-快速BS!C19)/0.75+快速PL!D6)/10000 -> 9242.9093 | R20: =L20-N20-O20-Q20 -> -11796.975
A21: 周转材料 | B21: 0 | C21: =精铸BS!C20+新材料BS!D20+快速BS!D20+热等静压BS!C20 -> 1114684.8 | D21: =(C21-B21)/B21 -> #DIV/0! | G21: 0 | H21: =(F22-G22)/F22 -> #DIV/0! | K21: =K19+K20 -> 1.4425197e+08 | L21: =L19+L20 -> 14425.197 | M21: 总产值 | N21: =N19+N20 -> 741.89983 | O21: =O19+O20 -> 16448.064 | P21: =Q21+R21 -> -2764.766 | Q21: =Q19+Q20 -> 8197.258 | R21: =L21-N21-O21-Q21 -> -10962.024
A22: 待摊费用 | D22: =(C22-B22)/B22 -> #DIV/0! | F22: 0 | G22: 0 | H22: =(F23-G23)/F23 -> #DIV/0!
A23: 合同资产 | B23: 2362972 | C23: =合并试算平衡表!K26 -> 1426653 | F23: 0 | G23: 0
A24: 一年内到期的非流动资产 | C24: =合并试算平衡表!K28 -> 0 | D24: =(C24-B24)/B24 -> #DIV/0! | H24: =(F25-G25)/F25 -> -0.26036356
A25: 其他流动资产 | B25: 27074.08 | C25: =合并试算平衡表!K29 -> 3625070.3 | D25: =(C25-B25)/B25 -> 132.89449 | E25: 流动负债合计 | F25: =SUM(F7:F23) -> 2.3511581e+08 | G25: =SUM(G7:G23) -> 2.963314e+08 | H25: =(F26-G26)/F26 -> #DIV/0! | I25: =G25/10000 -> 29633.14
A26: 流动资产合计 | B26: =B7+B10+B11+B12+B13+B16+B17+B22+B25+B23 -> 2.5476702e+08 | C26: =C7+C10+C11+C12+C13+C16+C17+C22+C25+C23 -> 3.0541432e+08 | D26: =(C26-B26)/B26 -> 0.19879849 | E26: 非流动负债： | F26: 0 | G26: 0 | H26: =(F27-G27)/F27 -> 0.0258 | K26: =K19/1.13+K20 -> 1.4346176e+08 | L26: =K26/10000 -> 14346.176 | M26: 工业销售产值 | N26: =((精铸BS!C18-精铸BS!B18+精铸BS!C19-精铸BS!B19)+精铸PL!C5)/10000 -> 728.79436 | O26: =((新材料BS!C18-新材料BS!B18+新材料BS!C19-新材料BS!B19)+新材料PL!C6)/10000 -> 730.52332 | P26: =Q26+R26 -> #VALUE! | Q26: =((快速BS!C18-快速BS!B18+快速BS!C19-快速BS!B19)+快速PL!C5)/10000 -> #VALUE! | R26: =L26-N26-O26-Q26 -> #VALUE!
A27: 非流动资产： | B27: 0 | C27: 0 | D27: =(C27-B27)/B27 -> #DIV/0! | E27: 长期借款 | F27: 50000000 | G27: =合并试算平衡表!K90 -> 48710000 | H27: =(F28-G28)/F28 -> #DIV/0!
A28: 可供出售金融资产 | C28: =合并试算平衡表!K33 -> 0 | D28: =(C28-B28)/B28 -> #DIV/0! | E28: 应付债券 | G28: =合并试算平衡表!K91 -> 0 | H28: =(F29-G29)/F29 -> 1
A29: 持有至到期投资 | C29: =合并试算平衡表!K34 -> 0 | D29: =(C29-B29)/B29 -> #DIV/0! | E29: 长期应付款 | F29: 2447726.5 | G29: =合并试算平衡表!K94 -> 0 | H29: =(F30-G30)/F30 -> #DIV/0!
A30: 长期应收款 | B30: 22650 | C30: =合并试算平衡表!K35 -> 0 | D30: =(C30-B30)/B30 -> -1 | E30: 专项应付款 | G30: 0 | H30: =(F31-G31)/F31 -> #DIV/0!
A31: 长期股权投资 | C31: =合并试算平衡表!K36 -> 0 | D31: =(C31-B31)/B31 -> #DIV/0! | E31: 预计负债 | H31: =(F33-G33)/F33 -> #DIV/0!
A32: 投资性房地产 | C32: =合并试算平衡表!K39 -> 0 | D32: =(C32-B32)/B32 -> #DIV/0! | E32: 递延收益 | F32: 5448006.8 | G32: =合并试算平衡表!K98 -> 33930809 | H32: =(F34-G34)/F34 -> #DIV/0!
A33: 固定资产原价 | B33: 3.2728959e+08 | C33: =合并试算平衡表!K40 -> 3.6376163e+08 | D33: =(C33-B33)/B33 -> 0.11143661 | E33: 递延所得税负债 | F33: 0 | G33: =合并试算平衡表!K99 -> 0 | H33: =(F35-G35)/F35 -> -0.42740758 | K33: =C33-B33 -> 36472042 | L33: =ROUND(K33/10000,2) -> 3647.2 | M33: 固定资产当年增加
A34: 减：累计折旧 | B34: 1.1518926e+08 | C34: =合并试算平衡表!K41 -> 1.6850946e+08 | D34: =(C34-B34)/B34 -> 0.46289213 | E34: 其他非流动负债 | F34: 0 | G34: =合并试算平衡表!K100 -> 0 | H34: =(F36-G36)/F36 -> -0.29336955 | K34: =C34-B34 -> 53320202 | L34: =ROUND(K34/10000,2) -> 5332.02 | M34: 当年累计折旧
A35: 固定资产净值 | B35: 2.1210033e+08 | C35: =C33-C34 -> 1.9525217e+08 | D35: =(C35-B35)/B35 -> -0.079434861 | E35: 非流动负债合计 | F35: =SUM(F27:F34) -> 57895733 | G35: =SUM(G27:G34) -> 82640809 | H35: =(F37-G37)/F37 -> #DIV/0! | J35: 存货跌价
A36: 在建工程 | B36: 16311725 | C36: =合并试算平衡表!K45 -> 42663260 | D36: =(C36-B36)/B36 -> 1.6154965 | E36: 负债合计 | F36: =F25+F35 -> 2.9301155e+08 | G36: =G25+G35 -> 3.7897221e+08 | H36: =(F38-G38)/F38 -> -0.009973253
A37: 工程物资 | C37: =合并试算平衡表!K46 -> 0 | D37: =(C37-B37)/B37 -> #DIV/0! | E37: 所有者权益（或股东权益）： | F37: 0 | G37: 0 | H37: =(F39-G39)/F39 -> -0.11786555 | K37: 13447321
A38: 固定资产清理 | C38: =合并试算平衡表!K47 -> 0 | D38: =(C38-B38)/B38 -> #DIV/0! | E38: 实收资本（或股本） | F38: 260216000 | G38: =合并试算平衡表!K104 -> 262811200 | H38: =(F40-G40)/F40 -> #DIV/0!
A39: 生产性生物资产 | C39: =合并试算平衡表!K48 -> 0 | D39: =(C39-B39)/B39 -> #DIV/0! | E39: 资本公积 | F39: 1.0524534e+08 | G39: =合并试算平衡表!K108 -> 1.1765014e+08 | H39: =(F41-G41)/F41 -> #DIV/0!
A40: 油气资产 | C40: =合并试算平衡表!K49 -> 0 | D40: =(C40-B40)/B40 -> #DIV/0! | E40: 减：库存股 | H40: =(F42-G42)/F42 -> -0.36391111
A41: 无形资产 | B41: 12866865 | C41: =合并试算平衡表!K50 -> 13011878 | D41: =(C41-B41)/B41 -> 0.011270254 | E41: 盈余公积 | F41: 0 | G41: =合并试算平衡表!K112 -> 0 | H41: =(F43-G43)/F43 -> 0.16567503
...

Sheet CF-合并
C1: 合并现金流量表
G2: 财会年企03表
A3: 单位:飞而康快速制造科技有限责任公司 | E3: =基本信息!B14 -> 45991 | G3: 金额单位：元
A4: 项 目 | B4: 行次 | C4: 本期金额 | D4: 本年累计 | E4: 项 目 | F4: 行次 | G4: 本期金额 | H4: 本年累计
A5: 一、经营活动产生的现金流量： | B5: 1 | C5: — | D5: — | E5: 处置固定资产、无形资产和其他长期资产所收回的现金净额 | F5: 30 | G5: 0 | H5: 0
A6: 销售商品、提供劳务收到的现金 | B6: 2 | C6: 10324670 | D6: 92773879 | E6: 处置子公司及其他营业单位收回的现金净额 | F6: 31 | G6: 0 | H6: 0
A7: 客户存款和同业存放款项净增加额 | B7: 3 | C7: 0 | D7: 0 | E7: 收到其他与投资活动有关的现金 | F7: 32 | G7: 0 | H7: 0
A8: 向中央银行借款净增加额 | B8: 4 | C8: 0 | D8: 0 | E8: 投资活动现金流入小计 | F8: 33 | G8: 0 | H8: 15360122
A9: 向其他金融机构拆入资金净增加额 | B9: 5 | C9: 0 | D9: 0 | E9: 购建固定资产、无形资产和其他长期资产所支付的现金 | F9: 34 | G9: 353274.28 | H9: 46108059
A10: 收到原保险合同保费取得的现金 | B10: 6 | C10: 0 | D10: 0 | E10: 投资支付的现金 | F10: 35 | G10: 0 | H10: 0
A11: 收到再保险业务现金净额 | B11: 7 | C11: 0 | D11: 0 | E11: 质押贷款净增加额 | F11: 36 | G11: 0 | H11: 0
A12: 保户储金及投资款净增加额 | B12: 8 | C12: 0 | D12: 0 | E12: 取得子公司及其他营业单位支付的现金净额 | F12: 37 | G12: 0 | H12: 0
A13: 处置交易性金融资产净增加额 | B13: 9 | C13: 0 | D13: 0 | E13: 支付其他与投资活动有关的现金 | F13: 38 | G13: 0 | H13: 0
A14: 收取利息、手续费及佣金的现金 | B14: 10 | C14: 0 | D14: 0 | E14: 投资活动现金流出小计 | F14: 39 | G14: 353274.28 | H14: 46108059
A15: 拆入资金净增加额 | B15: 11 | C15: 0 | D15: 0 | E15: 投资活动产生的现金流量净额 | F15: 40 | G15: -353274.28 | H15: -30747936
A16: 回购业务资金净增加额 | B16: 12 | C16: 0 | D16: 0 | E16: 三、筹资活动产生的现金流量： | F16: 41 | G16: 0 | H16: 0
A17: 收到的税费返还 | B17: 13 | C17: 0 | D17: 20027.64 | E17: 吸收投资收到的现金 | F17: 42 | G17: 0 | H17: 15000000
... A32: 收回投资收到的现金 | B32: 28 | C32: 0 | D32: 5206506.8 | E32: 六、期末现金及现金等价物余额 | F32: 57 | G32: 56240462 | H32: 56240462
A33: 取得投资收益收到的现金 | B33: 29 | C33: 0 | D33: 10153615 | H33: —
F35: 现金 | G35: 0
F36: 银行存款 | G36: ='BS-合并'!C10 -> 56240462
G37: =G35+G36-G32 -> 0

Sheet PL-3D板块
A1: 利润表-3D板块合并
D2: 会企02表
A3: 制表单位:飞而康快速制造科技有限责任公司 | B3: 报表期间: | C3: =基本信息!B14 -> 45991 | D3: 单位：人民币元
I4: =I10+Q10 -> 14483982 | J4: =I4-I5 -> -145517.08
I5: =I13+Q13 -> 14629499 | J5: =J4/I4 -> -0.010046759
A6: 账簿:快速主账簿 | I6: =(I9-I12)/I9 -> 0.82048805 | J6: =(J9-J12)/J9 -> 0.67156733 | K6: =(K9-K12)/K9 -> 0.29170846 | L6: =(L9-L12)/L9 -> 0.29636069 | M6: =(M9-M12)/M9 -> 0.23706395 | N6: =(N9-N12)/N9 -> 0.14129516 | Q6: =(Q9-Q12)/Q9 -> -0.14251784 | R6: =(R9-R12)/R9 -> 0.052130885
G7: 注意修改！！！ | Q7: =(Q10-Q13)/Q10 -> -0.14762921 | R7: =(R10-R13)/R10 -> 0.045573767
A8: 项目 | B8: 行次 | C8: 合并口径本期金额 | D8: 合并口径本年累计金额 | G8: ='PL-合并'!G8 -> 2510月金额 | H8: ='PL-合并'!H8 -> 2510月累计金额 | I8: 压块本月 | J8: 压块累计 | K8: 精铸本月 | L8: 精铸累计 | M8: 热等静压本月 | N8: 热等静压累计 | O8: 合并抵消还原本月 | P8: 合并抵消还原累计 | Q8: 快速+新材料本期金额 | R8: 快速+新材料本年累计金额 | V8: 2511
A9: 一、营业收入 | B9: 1 | C9: ='PL-合并'!C9 -> 16506857 | D9: ='PL-合并'!D9 -> 1.340243e+08 | G9: ='PL-合并'!G9 -> 11456714 | H9: ='PL-合并'!H9 -> 1.1751745e+08 | I9: =I10+I11 -> 2058368.1 | J9: =J10+J11 -> 20993026 | K9: =精铸PL新!C9 -> 1781043.7 | L9: =精铸PL新!D9 -> 7351863.7 | M9: =热等静压PL新!C5 -> 1093163.5 | N9: =热等静压PL新!D5 -> 20619623 | O9: =SUM(O10:O11) -> 993625.22 | P9: =SUM(P10:P11) -> 10417355 | Q9: =C9-K9-M9+O9-I9 -> 12567907 | R9: =D9-L9-N9+P9-J9 -> 95477146 | U9: 32808.32 | V9: 新材料-精铸背靠背收入
A10: 其中：主营业务收入 | B10: 2 | C10: ='PL-合并'!C10 -> 16463625 | D10: ='PL-合并'!D10 -> 1.3352726e+08 | G10: ='PL-合并'!G10 -> 11391609 | H10: ='PL-合并'!H10 -> 1.1706364e+08 | I10: 2058368.1 | J10: =10131427.43+1765210.62+1467695.58+1287249.56+1492267.26+1404913.27+1385893.81+2058368.14 -> 20993026 | K10: =精铸PL新!C10 -> 1781043.7 | L10: =精铸PL新!D10 -> 7349891.4 | M10: =热等静压PL新!C6 -> 1093163.5 | N10: =热等静压PL新!D6 -> 20418559 | O10: =32808.32+861756.23 -> 894564.55 | P10: =465301.04+8400223.07 -> 8865524.1 | Q10: =C10-K10-M10+O10-I10 -> 12425614 | R10: =D10-L10-N10+P10-J10 -> 93631310 | U10: 629897.81 | V10: 新材料-热压背靠背收入
A11: 其他业务收入 | B11: 3 | C11: ='PL-合并'!C11 -> 43232.51 | D11: ='PL-合并'!D11 -> 497041.45 | G11: ='PL-合并'!G11 -> 65104.29 | H11: ='PL-合并'!H11 -> 453808.94 | K11: =精铸PL新!C11 -> 0 | L11: =精铸PL新!D11 -> 1972.3 | M11: =热等静压PL新!C7 -> 0 | N11: =热等静压PL新!D7 -> 201064.85 | O11: 99060.67 | P11: =1350766.46+201064.85 -> 1551831.3 | Q11: =C11-K11-M11+O11 -> 142293.18 | R11: =D11-L11-N11+P11 -> 1845835.6 | U11: 13821276 | V11: 3D
A12: 减：营业成本 | B12: 4 | C12: ='PL-合并'!C12 -> 15830447 | D12: ='PL-合并'!D12 -> 1.1005757e+08 | G12: ='PL-合并'!G12 -> 11130393 | H12: ='PL-合并'!H12 -> 94227126 | I12: =I13+I14 -> 369501.68 | J12: =J13+J14 -> 6894795.4 | K12: =精铸PL新!C12 -> 1261498.2 | L12: =精铸PL新!D12 -> 5173060.3 | M12: =热等静压PL新!C8 -> 834013.87 | N12: =热等静压PL新!D8 -> 17706170 | O12: =O13+O14 -> 993625.22 | P12: =P13+P14 -> 10216291 | Q12: =C12-K12-M12+O12-I12 -> 14359058 | R12: =D12-L12-N12+P12-J12 -> 90499838 | U12: =SUM(U9:U11) -> 14483982 | V12: 合计
A13: 其中：主营业务成本 | B13: 5 | C13: ='PL-合并'!C13 -> 15830447 | D13: ='PL-合并'!D13 -> 1.1005757e+08 | G13: ='PL-合并'!G13 -> 11130393 | H13: ='PL-合并'!H13 -> 94227126 | I13: 369501.68 | J13: =1712108.95+1669124.73+1487436.38+284945.34+269605.24+225598.04+342447.42+253230.26+280797.4+369501.68 -> 6894795.4 | K13: =精铸PL新!C13 -> 1261498.2 | L13: =精铸PL新!D13 -> 5173060.3 | M13: =热等静压PL新!C9 -> 834013.87 | N13: =热等静压PL新!D9 -> 17491063 | O13: =O10 -> 894564.55 | P13: =P10 -> 8865524.1 | Q13: =C13-K13-M13+O13-I13 -> 14259998 | R13: =D13-L13-N13+P13-J13 -> 89364179 | U13: =U12-Q10-I10 -> -1.4202669e-08 | V13: check
A14: 其他业务成本 | B14: 6 | C14: ='PL-合并'!C14 -> 0 | D14: ='PL-合并'!D14 -> 0 | G14: ='PL-合并'!G14 -> 0 | H14: ='PL-合并'!H14 -> 0 | K14: =精铸PL新!C14 -> 0 | L14: =精铸PL新!D14 -> 0 | M14: =热等静压PL新!C10 -> 0 | N14: =热等静压PL新!D10 -> 215107.4 | O14: =O11-O16 -> 99060.67 | P14: =P11-P16 -> 1350766.5 | Q14: =C14-K14-M14+O14 -> 99060.67 | R14: =D14-L14-N14+P14 -> 1135659.1
A15: 税金及附加 | B15: 7 | C15: ='PL-合并'!C15 -> 82112.72 | D15: ='PL-合并'!D15 -> 829444.38 | G15: ='PL-合并'!G15 -> 69676.53 | H15: ='PL-合并'!H15 -> 747331.66 | K15: =精铸PL新!C15 -> 0 | L15: =精铸PL新!D15 -> 26359.78 | M15: =热等静压PL新!C11 -> 584.09 | N15: =热等静压PL新!D11 -> 7209.21 | Q15: =C15-K15-M15+O15 -> 81528.63 | R15: =D15-L15-N15+P15 -> 795875.39
A16: 销售费用 | B16: 8 | C16: ='PL-合并'!C16 -> 822770.64 | D16: ='PL-合并'!D16 -> 8045698 | G16: ='PL-合并'!G16 -> 649038.84 | H16: ='PL-合并'!H16 -> 7222927.3 | K16: =精铸PL新!C16 -> 65057.34 | L16: =精铸PL新!D16 -> 580641.56 | M16: =热等静压PL新!C12 -> 49638.71 | N16: =热等静压PL新!D12 -> 556431.11 | O16: 0 | P16: 201064.85 | Q16: =C16-K16-M16+O16 -> 708074.59 | R16: =D16-L16-N16+P16 -> 7109690.2
A17: 管理费用 | B17: 9 | C17: ='PL-合并'!C17 -> 1193327.4 | D17: ='PL-合并'!D17 -> 8350965.1 | G17: ='PL-合并'!G17 -> 828962.78 | H17: ='PL-合并'!H17 -> 7157637.6 | K17: =精铸PL新!C17 -> 1663.13 | L17: =精铸PL新!D17 -> 100618.84 | M17: =热等静压PL新!C13 -> 17274.27 | N17: =热等静压PL新!D13 -> 237860.86 | Q17: =C17-K17-M17+O17 -> 1174390 | R17: =D17-L17-N17+P17 -> 8012485.4
A18: 研发费用 | B18: 10 | C18: ='PL-合并'!C18 -> 4315088.8 | D18: ='PL-合并'!D18 -> 19920178 | G18: ='PL-合并'!G18 -> 1995821 | H18: ='PL-合并'!H18 -> 15605089 | K18: =精铸PL新!C18 -> 98901.62 | L18: =精铸PL新!D18 -> 1123957.1 | M18: =热等静压PL新!C14 -> 93227.55 | N18: =热等静压PL新!D14 -> 894023.38 | Q18: =C18-K18-M18+O18 -> 4122959.6 | R18: =D18-L18-N18+P18 -> 17902198
A19: 财务费用 | B19: 11 | C19: ='PL-合并'!C19 -> 468077.9 | D19: ='PL-合并'!D19 -> 4508765.3 | G19: ='PL-合并'!G19 -> 414734.8 | H19: ='PL-合并'!H19 -> 4040687.4 | K19: =精铸PL新!C19 -> 26950.51 | L19: =精铸PL新!D19 -> 185821.21 | M19: =热等静压PL新!C15 -> 270.22 | N19: =热等静压PL新!D15 -> 1051.76 | O19: 0 | P19: 0 | Q19: =C19-K19-M19+O19 -> 440857.17 | R19: =D19-L19-N19+P19 -> 4321892.3
A20: 其中：利息费用 | B20: 12 | C20: ='PL-合并'!C20 -> 458409.52 | D20: ='PL-合并'!D20 -> 4534024.2 | G20: ='PL-合并'!G20 -> 409021.01 | H20: ='PL-合并'!H20 -> 4075614.6 | K20: =精铸PL新!C20 -> 17172.28 | L20: =精铸PL新!D20 -> 193063.36 | M20: =热等静压PL新!C16 -> 0 | N20: =热等静压PL新!D16 -> 0 | Q20: =C20-K20-M20+O20 -> 441237.24 | R20: =D20-L20-N20+P20 -> 4340960.8
A21: 利息收入 | B21: 13 | C21: ='PL-合并'!C21 -> -232.59 | D21: ='PL-合并'!D21 -> -85075.68 | G21: ='PL-合并'!G21 -> 0 | H21: ='PL-合并'!H21 -> -84843.09 | K21: =精铸PL新!C21 -> -72.12 | L21: =精铸PL新!D21 -> -1409.16 | M21: =热等静压PL新!C17 -> 0 | N21: =热等静压PL新!D17 -> -1211.72 | Q21: =C21-K21-M21+O21 -> -160.47 | R21: =D21-L21-N21+P21 -> -82454.8
A22: 加：其他收益 | B22: 14 | C22: ='PL-合并'!C22 -> 250000 | D22: ='PL-合并'!D22 -> 1305528.3 | G22: ='PL-合并'!G22 -> 0 | H22: ='PL-合并'!H22 -> 1055528.3 | K22: =精铸PL新!C22 -> 0 | L22: =精铸PL新!D22 -> 34962.89 | M22: =热等静压PL新!C18 -> 0 | N22: =热等静压PL新!D18 -> 1843.34 | Q22: =C22-K22-M22+O22 -> 250000 | R22: =D22-L22-N22+P22 -> 1268722.1
A23: 投资收益（损失以“-”号填列） | B23: 15 | C23: ='PL-合并'!C23 -> 0 | D23: ='PL-合并'!D23 -> 853056.55 | G23: ='PL-合并'!G23 -> 0 | H23: ='PL-合并'!H23 -> 853056.55 | K23: =精铸PL新!C23 -> 0 | L23: =精铸PL新!D23 -> 0 | M23: =热等静压PL新!C19 -> 0 | N23: =热等静压PL新!D19 -> 0 | Q23: =C23-K23-M23+O23 -> 0 | R23: =D23-L23-N23+P23 -> 853056.55
A24: 其中：对联营企业和合营企业的投资收益 | B24: 16 | C24: ='PL-合并'!C24 -> 0 | D24: ='PL-合并'!D24 -> 0 | G24: ='PL-合并'!G24 -> 0 | H24: ='PL-合并'!H24 -> 0 | K24: =精铸PL新!C24 -> 0 | L24: =精铸PL新!D24 -> 0 | M24: =热等静压PL新!C20 -> 0 | N24: =热等静压PL新!D20 -> 0 | Q24: =C24-K24-M24+O24 -> 0 | R24: =D24-L24-N24+P24 -> 0
A25: 以摊余成本计量的金融资产终止确认收益（损失以“-”号填列） | B25: 17 | C25: ='PL-合并'!C25 -> 0 | D25: ='PL-合并'!D25 -> 0 | G25: ='PL-合并'!G25 -> 0 | H25: ='PL-合并'!H25 -> 0 | K25: =精铸PL新!C25 -> 0 | L25: =精铸PL新!D25 -> 0 | M25: =热等静压PL新!C21 -> 0 | N25: =热等静压PL新!D21 -> 0 | Q25: =C25-K25-M25+O25 -> 0 | R25: =D25-L25-N25+P25 -> 0
A26: 净敞口套期收益（损失以“-”号填列） | B26: 18 | C26: ='PL-合并'!C26 -> 0 | D26: ='PL-合并'!D26 -> 0 | G26: ='PL-合并'!G26 -> 0 | H26: ='PL-合并'!H26 -> 0 | K26: =精铸PL新!C26 -> 0 | L26: =精铸PL新!D26 -> 0 | M26: =热等静压PL新!C22 -> 0 | N26: =热等静压PL新!D22 -> 0 | Q26: =C26-K26-M26+O26 -> 0 | R26: =D26-L26-N26+P26 -> 0
A27: 公允价值变动收益（损失以“-”填列） | B27: 19 | C27: ='PL-合并'!C27 -> 0 | D27: ='PL-合并'!D27 -> 0 | G27: ='PL-合并'!G27 -> 0 | H27: ='PL-合并'!H27 -> 0 | K27: =精铸PL新!C27 -> 0 | L27: =精铸PL新!D27 -> 0 | M27: =热等静压PL新!C23 -> 0 | N27: =热等静压PL新!D23 -> 0 | Q27: =C27-K27-M27+O27 -> 0 | R27: =D27-L27-N27+P27 -> 0
A28: 信用减值损失（损失以“-”填列） | B28: 20 | C28: ='PL-合并'!C28 -> 0 | D28: ='PL-合并'!D28 -> -1780058.3 | G28: ='PL-合并'!G28 -> 0 | H28: ='PL-合并'!H28 -> -1780058.3 | K28: =精铸PL新!C28 -> 0 | L28: =精铸PL新!D28 -> 0 | M28: =热等静压PL新!C24 -> 0 | N28: =热等静压PL新!D24 -> -170766.3 | Q28: =C28-K28-M28+O28 -> 0 | R28: =D28-L28-N28+P28 -> -1609292
A29: 资产减值损失（损失以“-”填列） | B29: 21 | C29: ='PL-合并'!C29 -> 0 | D29: ='PL-合并'!D29 -> 0 | G29: ='PL-合并'!G29 -> 0 | H29: ='PL-合并'!H29 -> 0 | K29: =精铸PL新!C29 -> 0 | L29: =精铸PL新!D29 -> 0 | M29: =热等静压PL新!C25 -> 0 | N29: =热等静压PL新!D25 -> 0 | Q29: =C29-K29-M29+O29 -> 0 | R29: =D29-L29-N29+P29 -> 0
A30: 资产处置收益（损失以“-”填列） | B30: 22 | C30: ='PL-合并'!C30 -> 0 | D30: ='PL-合并'!D30 -> 0 | G30: ='PL-合并'!G30 -> 0 | H30: ='PL-合并'!H30 -> 0 | K30: =精铸PL新!C30 -> 0 | L30: =精铸PL新!D30 -> 0 | M30: =热等静压PL新!C26 -> 0 | N30: =热等静压PL新!D26 -> 0 | Q30: =C30-K30-M30+O30 -> 0 | R30: =D30-L30-N30+P30 -> 0
A31: 二、营业利润（亏损以“－”号填列） | B31: 23 | C31: ='PL-合并'!C31 -> -5954966.8 | D31: ='PL-合并'!D31 -> -17309794 | G31: ='PL-合并'!G31 -> -3631913.4 | H31: ='PL-合并'!H31 -> -11354828 | I31: =I9-I12 -> 1688866.5 | J31: =J9-J12 -> 14098230 | K31: =K9-K12-K15-K16-K17-K18-K19+K22+K23+K27+K28+K29+K30 -> 326972.92 | L31: =L9-L12-L15-L16-L17-L18-L19+L22+L23+L27+L28+L29+L30 -> 196367.74 | M31: =M9-M12-M15-M16-M17-M18-M19+M22+M23+M27+M28+M29+M30 -> 98154.83 | N31: =N9-N12-N15-N16-N17-N18-N19+N22+N23+N27+N28+N29+N30 -> 1047953.8 | Q31: =C31-K31-M31+O31-I31 -> -8068961.1 | R31: =D31-L31-N31+P31-J31 -> -32652346
A32: 加：营业外收入 | B32: 24 | C32: ='PL-合并'!C32 -> 0 | D32: ='PL-合并'!D32 -> 70120.03 | G32: ='PL-合并'!G32 -> 70000 | H32: ='PL-合并'!H32 -> 70120.03 | K32: =精铸PL新!C32 -> 0 | L32: =精铸PL新!D32 -> 0 | M32: =热等静压PL新!C28 -> 0 | N32: =热等静压PL新!D28 -> 0 | Q32: =C32-K32-M32+O32 -> 0 | R32: =D32-L32-N32+P32 -> 70120.03
A33: 减：营业外支出 | B33: 25 | C33: ='PL-合并'!C33 -> 0 | D33: ='PL-合并'!D33 -> 24203.21 | G33: ='PL-合并'!G33 -> 0.01 | H33: ='PL-合并'!H33 -> 24203.21 | K33: =精铸PL新!C33 -> 0 | L33: =精铸PL新!D33 -> 1714.8 | M33: =热等静压PL新!C29 -> 0 | N33: =热等静压PL新!D29 -> 0 | Q33: =C33-K33-M33+O33 -> 0 | R33: =D33-L33-N33+P33 -> 22488.41
A34: 三、利润总额（亏损以“－”号填列） | B34: 26 | C34: ='PL-合并'!C34 -> -5954966.8 | D34: ='PL-合并'!D34 -> -17263878 | G34: ='PL-合并'!G34 -> -3561913.4 | H34: ='PL-合并'!H34 -> -11308911 | I34: =I31+I32-I33 -> 1688866.5 | J34: =J31+J32-J33 -> 14098230 | K34: =K31+K32-K33 -> 326972.92 | L34: =L31+L32-L33 -> 194652.94 | M34: =M31+M32-M33 -> 98154.83 | N34: =N31+N32-N33 -> 1047953.8 | Q34: =C34-K34-M34+O34-I34 -> -8068961.1 | R34: =D34-L34-N34+P34-J34 -> -32604715
A35: 减：所得税费用 | B35: 27 | C35: ='PL-合并'!C35 -> 20876.67 | D35: ='PL-合并'!D35 -> 45634.12 | G35: ='PL-合并'!G35 -> 0 | H35: ='PL-合并'!H35 -> 24757.45 | K35: =精铸PL新!C35 -> 0 | L35: =精铸PL新!D35 -> 0 | M35: =热等静压PL新!C31 -> 20876.67 | N35: =热等静压PL新!D31 -> 45634.12 | Q35: =C35-K35-M35+O35 -> 0 | R35: =D35-L35-N35+P35 -> 0
A36: 四、净利润（净亏损以“－”号填列） | B36: 28 | C36: ='PL-合并'!C36 -> -5975843.5 | D36: ='PL-合并'!D36 -> -17309512 | G36: ='PL-合并'!G36 -> -3561913.4 | H36: ='PL-合并'!H36 -> -11333668 | I36: =I34-I35 -> 1688866.5 | J36: =J34-J35 -> 14098230 | K36: =K34-K35 -> 326972.92 | L36: =L34-L35 -> 194652.94 | M36: =M34-M35 -> 77278.16 | N36: =N34-N35 -> 1002319.6 | Q36: =C36-K36-M36+O36-I36 -> -8068961.1 | R36: =D36-L36-N36+P36-J36 -> -32604715
A37: 少数股东损益 | B37: 29 | C37: ='PL-合并'!C37 -> 72653.383 | D37: ='PL-合并'!D37 -> 43251.883 | G37: ='PL-合并'!G37 -> 35159.516 | H37: ='PL-合并'!H37 -> -29401.5 | K37: =精铸PL新!C37 -> 0 | L37: =精铸PL新!D37 -> 0 | M37: =热等静压PL新!C33 -> 0 | N37: =热等静压PL新!D33 -> 0
A38: 归属于母公司所有者的净利润 | B38: 30 | C38: ='PL-合并'!C38 -> -6048496.9 | D38: ='PL-合并'!D38 -> -17352764 | G38: ='PL-合并'!G38 -> -3597072.9 | H38: ='PL-合并'!H38 -> -11304267 | K38: =精铸PL新!C38 -> 0 | L38: =精铸PL新!D38 -> 0 | M38: =热等静压PL新!C34 -> 0 | N38: =热等静压PL新!D34 -> 0
A39: 五、其他综合收益的税后净额 | B39: 31
A40: （一）不能重分类进损益的其他综合收益 | B40: 32
...

Sheet 资产负债表-M
A1: 资产负债表
A3: 编制单位：飞而康快速制造科技有限责任公司 | C3: =基本信息!B14 -> 45991 | D3: 金额单位：人民币元
A4: 资 产 | B4: 附注 | C4: =C3 -> 45991 | D4: 45657
A7: 流动资产：
A8: 货币资金 | C8: ='BS-合并'!C9 -> 56972677 | D8: ='BS-合并'!B9 -> 49753272
A9: 以公允价值计量且其变动计入当期损益的金融资产
A10: 交易性金融资产 | C10: ='BS-合并'!C12 -> 0 | D10: 0
A11: 衍生金融资产
A12: 应收票据 | C12: ='BS-合并'!C13 -> 6766158.5 | D12: ='BS-合并'!B13 -> 29226386
A13: 应收账款 | C13: ='BS-合并'!C14 -> 1.1533203e+08 | D13: ='BS-合并'!B14 -> 86579419
A14: 应收款项融资 | C14: ='BS-合并'!C15 -> 0 | D14: ='BS-合并'!B15 -> 1603892.3
A15: 预付款项 | C15: ='BS-合并'!C16 -> 7259283.4 | D15: ='BS-合并'!B16 -> 4883049.8
A16: 其他应收款 | C16: ='BS-合并'!C17+'BS-合并'!C18+'BS-合并'!C19 -> 721163.11 | D16: ='BS-合并'!B19 -> 938609.95
A17: 存货 | C17: ='BS-合并'!C20 -> 1.1331129e+08 | D17: ='BS-合并'!B20 -> 89565843
A18: 合同资产 | C18: ='资产负债表-合并 (2)'!C23 -> 1426653 | D18: ='BS-合并'!B26 -> 5174733.3
A19: 持有待售资产
A20: 一年内到期的非流动资产 | C20: ='BS-合并'!C27 -> 0
A21: 其他流动资产 | C21: ='BS-合并'!C28 -> 3625070.3 | D21: ='BS-合并'!B28 -> 1383995.4
A25: 流动资产合计 | C25: =SUM(C8:C24) -> 3.0541432e+08 | D25: =SUM(D8:D24) -> 2.691092e+08 | F25: =C25-'BS-合并'!C29 -> 0 | H25: =D25-'BS-合并'!B29 -> 0
A26: 非流动资产：
A27: 债权投资
A28: 可供出售金融资产
A29: 其他债权投资
A30: 持有至到期投资
A31: 长期应收款 | C31: ='BS-合并'!C36 -> 0 | D31: 0
A32: 长期股权投资 | C32: ='BS-合并'!C37 -> 0 | D32: 0
A33: 其他权益工具投资
A34: 其他非流动金融资产 | C34: ='BS-合并'!C38 -> 3000000 | D34: ='BS-合并'!B38 -> 17507066
A35: 投资性房地产
